Workbook
Name benhVien: BenhVien!$A$3:$D$14894
Name danToc: 'Dân tộc'!$A$3:$B$58
Name huyen: Xa!$A$3:$D$3500
Name loai_khai_bao: 'Tổng hợp '!$B$25:$B$29
Name ma_huyen: Xa!$C$3:$C$3500
Name ma_huyen_xa: #REF!
Name ma_loai_phuong_an: 'Tổng hợp '!$D$43:$D$88
Name ma_mqh: 'Tổng hợp '!$J$15:$K$37
Name ma_phuong_an: 'Tổng hợp '!$C$43:$C$88
Name ma_tinh: Tinh!$B$3:$B$67
Name ma_tinh_benh_vien: TinhBenhVien!$B$3:$B$65
Name ma_tinh_bv: BenhVien!$D$3:$D$14894
Name ma_tinh_huyen: Xa!$D$3:$D$3500
Name ma_xa: #REF!
Name MaLoaiGiayTo: 'Tổng hợp '!$I$4:$I$8
Name mqh: 'Tổng hợp '!$J$15:$J$37
Name phuong_an: 'Tổng hợp '!$B$43:$D$88
Name quanhe: 'Tổng hợp '!$M$4:$N$26
Name quocTich: QuocTich!$A$3:$B$243
Name ten_danToc: 'Dân tộc'!$A$3:$A$58
Name ten_huyen: Xa!$B$3:$B$3500
Name ten_phuong_an: 'Tổng hợp '!$B$43:$B$88
Name ten_quoctich: QuocTich!$A$3:$A$243
Name ten_tinh: Tinh!$A$3:$A$67
Name ten_tinh_Benh_vien: TinhBenhVien!$A$3:$A$65
Name ten_xa: #REF!
Name tinh: Tinh!$A$3:$B$67
Name TinhBenhVien: TinhBenhVien!$A$3:$B$65
Name xa: #REF!

Sheet Dữ Liệu
A1: CHÚ Ý: Những cột màu xanh đậm là bắt buộc phải nhập; Dữ liệu nhập bắt đầu từ dòng thứ 4. | C1: tra cứu tại https://baohiemxahoi.gov.vn/tracuu/Pages/tra-cuu-ho-gia-dinh.aspx | K1: chỉ dành cho những lao động đóng theo hệ số lương. Lao động đóng theo tiền lương KHÔNG NHẬP cột này | N1: Chỉ được nhập số tiền, KHÔNG CHO PHÉP nhập hệ số | R1: Nhập khi Giảm hẳn do chết | S1: tăng mới điền số HĐLĐ, mã bệnh viện KCB ban đầu - mã phương án sẽ được tự động điền vào Ghi chú khi import file vào phần mềm. | T1: Dùng dấu phẩy để phân tách hàng thập phân | U1: 0: không 1:có | V1: 0: không 1:có | Y1: K1: nơi người dân tộc thiểu số, người nghèo sống tại địa bàn khó khăn K2: nơi người dân tộc thiểu số, người nghèo sống tại địa bàn đặc biệt khó khăn K3: Nơi người tham gia BHYT sống tại xã đảo, huyện đảo Nếu không thuộc 3 khu vực trên thì để trống. | Z1: Tra cứu tại: https://docs.google.com/spreadsheets/d/1fmVEVFMvAZ6-KVTAwfg89OH5ejjPNvdcgNos1aHRGC4/edit?usp=sharing | AA1: Điền x nếu muốn phần mềm lưu lại những thông tin của tờ khai TK1. Nếu không điền x, những thông tin tờ Tk1 sẽ không được lưu lại. | AD1: ngày/tháng/năm tháng/năm hoặc năm sinh | AE1: Nam:1 Nữ: 0 | AH1: tra cứu những dân tộc khác tên nhưng cùng mã với nhau tại sheet Dân tộc | AJ1: Nơi đăng ký khám chữa bệnh ban đầu | AN1: Địa chỉ Khai Sinh (Nhập hoặc chọn tên tỉnh/huyện/xã, cột mã là tự sinh) | AT1: Địa chỉ liên hệ (Nhập hoặc chọn tên tỉnh/xã, cột mã là tự sinh) | BC1: Dành cho đối tượng tự nguyện | BE1: ghi yêu cầu cấp số/thẻ hoặc cả 2. trường hợp cấp lại sổ do mất/hỏng ghi quá trình đóng | BI1: Giữ vị trí việc làm là nhà quản lý | BK1: Giữ vị trí việc Chuyên môn kỹ thuật bậc cao | BM1: Giữ vị trí việc Chuyên môn kỹ thuật bậc trung | BO1: Giữ vị trí việc làm khác | BQ1: Ngành nghề nặng nhọc độc hại | BT1: Hợp đồng lao động xác định thời hạn | BV1: Hợp đồng lao động khác (dưới 1 tháng, thử việc) | BX1: Không nhận:0 Nhận:1 | BY1: Không nhận:0 Nhận:1 | BZ1: Số nhà, thôn/xóm,.. | CA1: Địa chỉ nhận bản giấy (Nhập hoặc chọn tên tỉnh/xã, cột mã là tự sinh)
A2: ID Lao động | B2: Họ tên | C2: Mã số BHXH | D2: Loại khai báo | E2: Mã loại khai báo | F2: Phương án | G2: Mã Phương án | H2: Chức vụ | I2: Nơi làm việc | J2: Tiền lương/ Hệ số lương | K2: Phụ cấp CV | L2: Phụ cấp TNVK (%) | M2: Phụ cấp TN Nghề (%) | N2: Phụ cấp lương | O2: Phụ cấp bổ sung | P2: Từ tháng | Q2: Đến tháng | R2: Ngày chết | S2: Ghi chú | T2: Tỷ lệ đóng(%) | U2: Tính lãi | V2: Đã có sổ | W2: Mức hưởng BHYT | X2: Phòng ban làm việc | Y2: Mã vùng sinh sống | Z2: Mã vùng lương tối thiểu | AA2: Bổ sung thêm TK1 | AB2: CMND | AC2: Mã hộ gia đình | AD2: Ngày sinh | AE2: Giới tính | AF2: Quốc tịch | AG2: Mã quốc tịch | AH2: Dân tộc | AI2: Mã Dân tộc | AJ2: Tỉnh - Bệnh viện | AK2: Mã Tỉnh - Bệnh viện | AL2: Bệnh viện (KCB ban đầu) | AM2: Mã Bệnh viện | AN2: Tỉnh - Khai sinh | AO2: Mã Tỉnh - Khai sinh | AP2: Xã - Khai sinh | AQ2: Mã xã - Khai sinh | AR2: Xã - Khai sinh | AS2: Mã xã - Khai sinh | AT2: Tỉnh - Địa chỉ liên hệ | AU2: Mã tỉnh - Địa chỉ liên hệ | AV2: Xã - Địa chỉ liên hệ | AW2: Mã xã - Địa chỉ liên hệ | AX2: Xã - Địa chỉ liên hệ | AY2: Mã xã - Địa chỉ liên hệ | AZ2: Địa chỉ nhận hồ sơ | BA2: Tên cha/mẹ/người giám hộ | BB2: Điện thoại liên hệ | BC2: Mức tiền đóng | BD2: Phương thức đóng | BE2: Nội dung yêu cầu thay đổi | BF2: Hồ sơ kèm theo | BG2: Email liên hệ | BH2: Địa chỉ khai sinh | BI2: Ngày bắt đầu | BJ2: Ngày kết thúc | BK2: Ngày bắt đầu | BL2: Ngày kết thúc | BM2: Ngày bắt đầu | BN2: Ngày kết thúc | BO2: Ngày bắt đầu | BP2: Ngày kết thúc | BQ2: Ngày bắt đầu | BR2: Ngày kết thúc | BS2: Ngày bắt đầu hợp đồng lao động không xác định thời hạn | BT2: Ngày bắt đầu | BU2: Ngày kết thúc | BV2: Ngày bắt đầu | BW2: Ngày kết thúc | BX2: Nhận bản điện tử | BY2: Nhận bản giấy | BZ2: Địa chỉ nhận bản giấy | CA2: Tỉnh - Địa chỉ nhận bản giấy | CB2: Mã tỉnh - Địa chỉ nhận bản giấy | CC2: Xã - Địa chỉ nhận bản giấy | CD2: Xã - Địa chỉ nhận bản giấy
A3: STT | B3: HoTen | C3: MasoBHXH | D3: TenLoaiKhaiBao | E3: Loai | F3: TenPhuongAn | G3: PA | H3: ChucVu | I3: NoiLamViec | J3: TienLuong | K3: PhuCapCV | L3: PhuCapTNVK | M3: PhuCapTNNghe | N3: PhuCapLuong | O3: PhuCapBosung | P3: TuThang | Q3: DenThang | R3: NgayChet | S3: Ghichu | T3: TyleDong | U3: TinhLai | V3: DaCoSo | W3: MucHuong | X3: MaPhongBan | Y3: MavungSS | Z3: MavungLTT | AA3: Tk1_Save | AB3: CMND | AC3: Maho_Giadinh | AD3: NgaySinh | AE3: GioiTinh | AF3: TenQuocTich | AG3: QuocTich | AH3: TenDanToc | AI3: DanToc | AJ3: TenTinhBenhVien | AK3: MaTinhBenhVien | AL3: TenBenhVien | AM3: MaBenhVien | AN3: TenTinhKS | AO3: Matinh_KS | AP3: TenXaKS | AQ3: Maxa_KS | AT3: TenTinhNN | AU3: Matinh_NN | AV3: TenXaNN | AW3: Maxa_NN | AX3: TenXaNN | AY3: Maxa_NN | AZ3: Diachi_NN | BA3: Ten_ChaMe_Giamho | BB3: Dienthoai_LH | BC3: Mucdong | BD3: Phuongthuc | BE3: Noidung_Thaydoi | BF3: HosoKemtheo | BG3: Email_LH | BH3: Diachi_KS | BI3: Vtvl_nql_tungay | BJ3: Vtvl_nql_denngay | BK3: Vtvl_cmktbc_tungay | BL3: Vtvl_cmktbc_denngay | BM3: Vtvl_cmktbt_tungay | BN3: Vtvl_cmktbt_denngay | BO3: Vtvl_khac_tungay | BP3: Vtvl_khac_denngay | BQ3: Nndh_tungay | BR3: Nndh_denngay | BS3: Hdld_tungay | BT3: Hdld_xdth_tungay | BU3: Hdld_xdth_denngay | BV3: Hdld_khac_tungay | BW3: Hdld_khac_denngay | BX3: Nhan_BanDientu | BY3: Nhan_Bangiay | BZ3: Diachi_NhanBangiay | CA3: Tinh_NhanBangiay | CB3: Matinh_NhanBangiay | CC3: Xa_NhanBangiay | CD3: Maxa_NhanBangiay
E4: =IF(ISNA(VLOOKUP(D4,'Tổng hợp '!$B$25:$C$29,2,FALSE)),"",VLOOKUP(D4,'Tổng hợp '!$B$25:$C$29,2,FALSE)) | G4: =IF(ISNA(VLOOKUP(F4,phuong_an,2,FALSE)),"",VLOOKUP(F4,phuong_an,2,FALSE)) | AG4: =IF(ISNA(VLOOKUP(AF4,quocTich,2,FALSE)),"",VLOOKUP(AF4,quocTich,2,FALSE)) | AI4: =IF(ISNA(VLOOKUP(AH4,danToc,2,FALSE)),"",VLOOKUP(AH4,danToc,2,FALSE)) | AM4: =IF(ISNA(VLOOKUP(AL4&AK4,benhVien,3,FALSE)),"",VLOOKUP(AL4&AK4,benhVien,3,FALSE)) -> 0 | AO4: =IF(ISNA(VLOOKUP(AN4,tinh,2,FALSE)),"",VLOOKUP(AN4,tinh,2,FALSE)) | AQ4: =IF(ISNA(VLOOKUP(AP4&AO4,huyen,3,FALSE)),"",VLOOKUP(AP4&AO4,huyen,3,FALSE)) | AU4: 19 | AW4: =IF(ISNA(VLOOKUP(AV4&AU4,huyen,3,FALSE)),"",VLOOKUP(AV4&AU4,huyen,3,FALSE))
E5: =IF(ISNA(VLOOKUP(D5,'Tổng hợp '!$B$25:$C$29,2,FALSE)),"",VLOOKUP(D5,'Tổng hợp '!$B$25:$C$29,2,FALSE)) | G5: =IF(ISNA(VLOOKUP(F5,phuong_an,2,FALSE)),"",VLOOKUP(F5,phuong_an,2,FALSE)) | AG5: =IF(ISNA(VLOOKUP(AF5,quocTich,2,FALSE)),"",VLOOKUP(AF5,quocTich,2,FALSE)) | AI5: =IF(ISNA(VLOOKUP(AH5,danToc,2,FALSE)),"",VLOOKUP(AH5,danToc,2,FALSE)) | AM5: =IF(ISNA(VLOOKUP(AL5&AK5,benhVien,3,FALSE)),"",VLOOKUP(AL5&AK5,benhVien,3,FALSE)) -> 0 | AO5: =IF(ISNA(VLOOKUP(AN5,tinh,2,FALSE)),"",VLOOKUP(AN5,tinh,2,FALSE)) | AQ5: =IF(ISNA(VLOOKUP(AP5&AO5,huyen,3,FALSE)),"",VLOOKUP(AP5&AO5,huyen,3,FALSE)) | AU5: 19 | AW5: =IF(ISNA(VLOOKUP(AV5&AU5,huyen,3,FALSE)),"",VLOOKUP(AV5&AU5,huyen,3,FALSE))
E6: =IF(ISNA(VLOOKUP(D6,'Tổng hợp '!$B$25:$C$29,2,FALSE)),"",VLOOKUP(D6,'Tổng hợp '!$B$25:$C$29,2,FALSE)) | G6: =IF(ISNA(VLOOKUP(F6,phuong_an,2,FALSE)),"",VLOOKUP(F6,phuong_an,2,FALSE)) | AG6: =IF(ISNA(VLOOKUP(AF6,quocTich,2,FALSE)),"",VLOOKUP(AF6,quocTich,2,FALSE)) | AI6: =IF(ISNA(VLOOKUP(AH6,danToc,2,FALSE)),"",VLOOKUP(AH6,danToc,2,FALSE)) | AM6: =IF(ISNA(VLOOKUP(AL6&AK6,benhVien,3,FALSE)),"",VLOOKUP(AL6&AK6,benhVien,3,FALSE)) -> 0 | AO6: =IF(ISNA(VLOOKUP(AN6,tinh,2,FALSE)),"",VLOOKUP(AN6,tinh,2,FALSE)) | AQ6: =IF(ISNA(VLOOKUP(AP6&AO6,huyen,3,FALSE)),"",VLOOKUP(AP6&AO6,huyen,3,FALSE)) | AU6: 19 | AW6: =IF(ISNA(VLOOKUP(AV6&AU6,huyen,3,FALSE)),"",VLOOKUP(AV6&AU6,huyen,3,FALSE))
E7: =IF(ISNA(VLOOKUP(D7,'Tổng hợp '!$B$25:$C$29,2,FALSE)),"",VLOOKUP(D7,'Tổng hợp '!$B$25:$C$29,2,FALSE)) | G7: =IF(ISNA(VLOOKUP(F7,phuong_an,2,FALSE)),"",VLOOKUP(F7,phuong_an,2,FALSE)) | AG7: =IF(ISNA(VLOOKUP(AF7,quocTich,2,FALSE)),"",VLOOKUP(AF7,quocTich,2,FALSE)) | AI7: =IF(ISNA(VLOOKUP(AH7,danToc,2,FALSE)),"",VLOOKUP(AH7,danToc,2,FALSE)) | AM7: =IF(ISNA(VLOOKUP(AL7&AK7,benhVien,3,FALSE)),"",VLOOKUP(AL7&AK7,benhVien,3,FALSE)) -> 0 | AO7: =IF(ISNA(VLOOKUP(AN7,tinh,2,FALSE)),"",VLOOKUP(AN7,tinh,2,FALSE)) | AQ7: =IF(ISNA(VLOOKUP(AP7&AO7,huyen,3,FALSE)),"",VLOOKUP(AP7&AO7,huyen,3,FALSE)) | AU7: 19 | AW7: =IF(ISNA(VLOOKUP(AV7&AU7,huyen,3,FALSE)),"",VLOOKUP(AV7&AU7,huyen,3,FALSE))
E8: =IF(ISNA(VLOOKUP(D8,'Tổng hợp '!$B$25:$C$29,2,FALSE)),"",VLOOKUP(D8,'Tổng hợp '!$B$25:$C$29,2,FALSE)) | G8: =IF(ISNA(VLOOKUP(F8,phuong_an,2,FALSE)),"",VLOOKUP(F8,phuong_an,2,FALSE)) | AG8: =IF(ISNA(VLOOKUP(AF8,quocTich,2,FALSE)),"",VLOOKUP(AF8,quocTich,2,FALSE)) | AI8: =IF(ISNA(VLOOKUP(AH8,danToc,2,FALSE)),"",VLOOKUP(AH8,danToc,2,FALSE)) | AM8: =IF(ISNA(VLOOKUP(AL8&AK8,benhVien,3,FALSE)),"",VLOOKUP(AL8&AK8,benhVien,3,FALSE)) -> 0 | AO8: =IF(ISNA(VLOOKUP(AN8,tinh,2,FALSE)),"",VLOOKUP(AN8,tinh,2,FALSE)) | AQ8: =IF(ISNA(VLOOKUP(AP8&AO8,huyen,3,FALSE)),"",VLOOKUP(AP8&AO8,huyen,3,FALSE)) | AU8: 19 | AW8: =IF(ISNA(VLOOKUP(AV8&AU8,huyen,3,FALSE)),"",VLOOKUP(AV8&AU8,huyen,3,FALSE))
E9: =IF(ISNA(VLOOKUP(D9,'Tổng hợp '!$B$25:$C$29,2,FALSE)),"",VLOOKUP(D9,'Tổng hợp '!$B$25:$C$29,2,FALSE)) | G9: =IF(ISNA(VLOOKUP(F9,phuong_an,2,FALSE)),"",VLOOKUP(F9,phuong_an,2,FALSE)) | AG9: =IF(ISNA(VLOOKUP(AF9,quocTich,2,FALSE)),"",VLOOKUP(AF9,quocTich,2,FALSE)) | AI9: =IF(ISNA(VLOOKUP(AH9,danToc,2,FALSE)),"",VLOOKUP(AH9,danToc,2,FALSE)) | AM9: =IF(ISNA(VLOOKUP(AL9&AK9,benhVien,3,FALSE)),"",VLOOKUP(AL9&AK9,benhVien,3,FALSE)) -> 0 | AO9: =IF(ISNA(VLOOKUP(AN9,tinh,2,FALSE)),"",VLOOKUP(AN9,tinh,2,FALSE)) | AQ9: =IF(ISNA(VLOOKUP(AP9&AO9,huyen,3,FALSE)),"",VLOOKUP(AP9&AO9,huyen,3,FALSE)) | AU9: 19 | AW9: =IF(ISNA(VLOOKUP(AV9&AU9,huyen,3,FALSE)),"",VLOOKUP(AV9&AU9,huyen,3,FALSE))
E10: =IF(ISNA(VLOOKUP(D10,'Tổng hợp '!$B$25:$C$29,2,FALSE)),"",VLOOKUP(D10,'Tổng hợp '!$B$25:$C$29,2,FALSE)) | G10: =IF(ISNA(VLOOKUP(F10,phuong_an,2,FALSE)),"",VLOOKUP(F10,phuong_an,2,FALSE)) | AG10: =IF(ISNA(VLOOKUP(AF10,quocTich,2,FALSE)),"",VLOOKUP(AF10,quocTich,2,FALSE)) | AI10: =IF(ISNA(VLOOKUP(AH10,danToc,2,FALSE)),"",VLOOKUP(AH10,danToc,2,FALSE)) | AM10: =IF(ISNA(VLOOKUP(AL10&AK10,benhVien,3,FALSE)),"",VLOOKUP(AL10&AK10,benhVien,3,FALSE)) -> 0 | AO10: =IF(ISNA(VLOOKUP(AN10,tinh,2,FALSE)),"",VLOOKUP(AN10,tinh,2,FALSE)) | AQ10: =IF(ISNA(VLOOKUP(AP10&AO10,huyen,3,FALSE)),"",VLOOKUP(AP10&AO10,huyen,3,FALSE)) | AU10: 19 | AW10: =IF(ISNA(VLOOKUP(AV10&AU10,huyen,3,FALSE)),"",VLOOKUP(AV10&AU10,huyen,3,FALSE))
E51: =IF(ISNA(VLOOKUP(D51,'Tổng hợp '!$B$25:$C$29,2,FALSE)),"",VLOOKUP(D51,'Tổng hợp '!$B$25:$C$29,2,FALSE)) | G51: =IF(ISNA(VLOOKUP(F51,phuong_an,2,FALSE)),"",VLOOKUP(F51,phuong_an,2,FALSE)) | H51: =+VLOOKUP(A51,[1]VT!$C:$I,7,0) -> #N/A | J51: =+VLOOKUP(A51,[1]VT!$C:$M,11,0) -> #N/A | AG51: =IF(ISNA(VLOOKUP(AF51,quocTich,2,FALSE)),"",VLOOKUP(AF51,quocTich,2,FALSE)) | AH51: =+VLOOKUP(A51,'[2]Thông tin công nhân'!$C:$P,14,0) -> #N/A | AI51: =IF(ISNA(VLOOKUP(AH51,danToc,2,FALSE)),"",VLOOKUP(AH51,danToc,2,FALSE)) | AK51: =IF(ISNA(VLOOKUP(AJ51,TinhBenhVien!A:B,2,FALSE)),"",VLOOKUP(AJ51,TinhBenhVien!A:B,2,FALSE)) | AM51: =IF(ISNA(VLOOKUP(AL51&AK51,benhVien,3,FALSE)),"",VLOOKUP(AL51&AK51,benhVien,3,FALSE)) -> 0 | AN51: ="tỉnh"&" "&VLOOKUP(A51,'[2]Thông tin công nhân'!$C:$AI,31,0) -> #N/A | AO51: =IF(ISNA(VLOOKUP(AN51,tinh,2,FALSE)),"",VLOOKUP(AN51,tinh,2,FALSE)) | AP51: ="xã"&" "&VLOOKUP(A51,'[2]Thông tin công nhân'!$C:$AI,33,0) -> #N/A | AQ51: =IF(ISNA(VLOOKUP(AP51&AO51,huyen,3,FALSE)),"",VLOOKUP(AP51&AO51,huyen,3,FALSE)) | AS51: =IF(ISNA(VLOOKUP(AR51&AQ51,xa,3,FALSE)),"",VLOOKUP(AR51&AQ51,xa,3,FALSE)) -> #REF! | AU51: =IF(ISNA(VLOOKUP(AT51,tinh,2,FALSE)),"",VLOOKUP(AT51,tinh,2,FALSE)) | AW51: =IF(ISNA(VLOOKUP(AV51&AU51,huyen,3,FALSE)),"",VLOOKUP(AV51&AU51,huyen,3,FALSE)) | AY51: =IF(ISNA(VLOOKUP(AX51&AW51,xa,3,FALSE)),"",VLOOKUP(AX51&AW51,xa,3,FALSE)) -> #REF! | CB51: =IF(ISNA(VLOOKUP(CA51,tinh,2,FALSE)),"",VLOOKUP(CA51,tinh,2,FALSE)) | CD51: =IF(ISNA(VLOOKUP(CC51&CB51,huyen,3,FALSE)),"",VLOOKUP(CC51&CB51,huyen,3,FALSE))
E52: =IF(ISNA(VLOOKUP(D52,'Tổng hợp '!$B$25:$C$29,2,FALSE)),"",VLOOKUP(D52,'Tổng hợp '!$B$25:$C$29,2,FALSE)) | G52: =IF(ISNA(VLOOKUP(F52,phuong_an,2,FALSE)),"",VLOOKUP(F52,phuong_an,2,FALSE)) | H52: =+VLOOKUP(A52,[1]VT!$C:$I,7,0) -> #N/A | J52: =+VLOOKUP(A52,[1]VT!$C:$M,11,0) -> #N/A | AG52: =IF(ISNA(VLOOKUP(AF52,quocTich,2,FALSE)),"",VLOOKUP(AF52,quocTich,2,FALSE)) | AH52: =+VLOOKUP(A52,'[2]Thông tin công nhân'!$C:$P,14,0) -> #N/A | AI52: =IF(ISNA(VLOOKUP(AH52,danToc,2,FALSE)),"",VLOOKUP(AH52,danToc,2,FALSE)) | AK52: =IF(ISNA(VLOOKUP(AJ52,TinhBenhVien!A:B,2,FALSE)),"",VLOOKUP(AJ52,TinhBenhVien!A:B,2,FALSE)) | AM52: =IF(ISNA(VLOOKUP(AL52&AK52,benhVien,3,FALSE)),"",VLOOKUP(AL52&AK52,benhVien,3,FALSE)) -> 0 | AN52: ="tỉnh"&" "&VLOOKUP(A52,'[2]Thông tin công nhân'!$C:$AI,31,0) -> #N/A | AO52: =IF(ISNA(VLOOKUP(AN52,tinh,2,FALSE)),"",VLOOKUP(AN52,tinh,2,FALSE)) | AP52: ="xã"&" "&VLOOKUP(A52,'[2]Thông tin công nhân'!$C:$AI,33,0) -> #N/A | AQ52: =IF(ISNA(VLOOKUP(AP52&AO52,huyen,3,FALSE)),"",VLOOKUP(AP52&AO52,huyen,3,FALSE)) | AS52: =IF(ISNA(VLOOKUP(AR52&AQ52,xa,3,FALSE)),"",VLOOKUP(AR52&AQ52,xa,3,FALSE)) -> #REF! | AU52: =IF(ISNA(VLOOKUP(AT52,tinh,2,FALSE)),"",VLOOKUP(AT52,tinh,2,FALSE)) | AW52: =IF(ISNA(VLOOKUP(AV52&AU52,huyen,3,FALSE)),"",VLOOKUP(AV52&AU52,huyen,3,FALSE)) | AY52: =IF(ISNA(VLOOKUP(AX52&AW52,xa,3,FALSE)),"",VLOOKUP(AX52&AW52,xa,3,FALSE)) -> #REF! | CB52: =IF(ISNA(VLOOKUP(CA52,tinh,2,FALSE)),"",VLOOKUP(CA52,tinh,2,FALSE)) | CD52: =IF(ISNA(VLOOKUP(CC52&CB52,huyen,3,FALSE)),"",VLOOKUP(CC52&CB52,huyen,3,FALSE))
E53: =IF(ISNA(VLOOKUP(D53,'Tổng hợp '!$B$25:$C$29,2,FALSE)),"",VLOOKUP(D53,'Tổng hợp '!$B$25:$C$29,2,FALSE)) | G53: =IF(ISNA(VLOOKUP(F53,phuong_an,2,FALSE)),"",VLOOKUP(F53,phuong_an,2,FALSE)) | H53: =+VLOOKUP(A53,[1]VT!$C:$I,7,0) -> #N/A | J53: =+VLOOKUP(A53,[1]VT!$C:$M,11,0) -> #N/A | AG53: =IF(ISNA(VLOOKUP(AF53,quocTich,2,FALSE)),"",VLOOKUP(AF53,quocTich,2,FALSE)) | AH53: =+VLOOKUP(A53,'[2]Thông tin công nhân'!$C:$P,14,0) -> #N/A | AI53: =IF(ISNA(VLOOKUP(AH53,danToc,2,FALSE)),"",VLOOKUP(AH53,danToc,2,FALSE)) | AK53: =IF(ISNA(VLOOKUP(AJ53,TinhBenhVien!A:B,2,FALSE)),"",VLOOKUP(AJ53,TinhBenhVien!A:B,2,FALSE)) | AM53: =IF(ISNA(VLOOKUP(AL53&AK53,benhVien,3,FALSE)),"",VLOOKUP(AL53&AK53,benhVien,3,FALSE)) -> 0 | AN53: ="tỉnh"&" "&VLOOKUP(A53,'[2]Thông tin công nhân'!$C:$AI,31,0) -> #N/A | AO53: =IF(ISNA(VLOOKUP(AN53,tinh,2,FALSE)),"",VLOOKUP(AN53,tinh,2,FALSE)) | AP53: ="xã"&" "&VLOOKUP(A53,'[2]Thông tin công nhân'!$C:$AI,33,0) -> #N/A | AQ53: =IF(ISNA(VLOOKUP(AP53&AO53,huyen,3,FALSE)),"",VLOOKUP(AP53&AO53,huyen,3,FALSE)) | AS53: =IF(ISNA(VLOOKUP(AR53&AQ53,xa,3,FALSE)),"",VLOOKUP(AR53&AQ53,xa,3,FALSE)) -> #REF! | AU53: =IF(ISNA(VLOOKUP(AT53,tinh,2,FALSE)),"",VLOOKUP(AT53,tinh,2,FALSE)) | AW53: =IF(ISNA(VLOOKUP(AV53&AU53,huyen,3,FALSE)),"",VLOOKUP(AV53&AU53,huyen,3,FALSE)) | AY53: =IF(ISNA(VLOOKUP(AX53&AW53,xa,3,FALSE)),"",VLOOKUP(AX53&AW53,xa,3,FALSE)) -> #REF! | CB53: =IF(ISNA(VLOOKUP(CA53,tinh,2,FALSE)),"",VLOOKUP(CA53,tinh,2,FALSE)) | CD53: =IF(ISNA(VLOOKUP(CC53&CB53,huyen,3,FALSE)),"",VLOOKUP(CC53&CB53,huyen,3,FALSE))
E54: =IF(ISNA(VLOOKUP(D54,'Tổng hợp '!$B$25:$C$29,2,FALSE)),"",VLOOKUP(D54,'Tổng hợp '!$B$25:$C$29,2,FALSE)) | G54: =IF(ISNA(VLOOKUP(F54,phuong_an,2,FALSE)),"",VLOOKUP(F54,phuong_an,2,FALSE)) | H54: =+VLOOKUP(A54,[1]VT!$C:$I,7,0) -> #N/A | J54: =+VLOOKUP(A54,[1]VT!$C:$M,11,0) -> #N/A | AG54: =IF(ISNA(VLOOKUP(AF54,quocTich,2,FALSE)),"",VLOOKUP(AF54,quocTich,2,FALSE)) | AH54: =+VLOOKUP(A54,'[2]Thông tin công nhân'!$C:$P,14,0) -> #N/A | AI54: =IF(ISNA(VLOOKUP(AH54,danToc,2,FALSE)),"",VLOOKUP(AH54,danToc,2,FALSE)) | AK54: =IF(ISNA(VLOOKUP(AJ54,TinhBenhVien!A:B,2,FALSE)),"",VLOOKUP(AJ54,TinhBenhVien!A:B,2,FALSE)) | AM54: =IF(ISNA(VLOOKUP(AL54&AK54,benhVien,3,FALSE)),"",VLOOKUP(AL54&AK54,benhVien,3,FALSE)) -> 0 | AN54: ="tỉnh"&" "&VLOOKUP(A54,'[2]Thông tin công nhân'!$C:$AI,31,0) -> #N/A | AO54: =IF(ISNA(VLOOKUP(AN54,tinh,2,FALSE)),"",VLOOKUP(AN54,tinh,2,FALSE)) | AP54: ="xã"&" "&VLOOKUP(A54,'[2]Thông tin công nhân'!$C:$AI,33,0) -> #N/A | AQ54: =IF(ISNA(VLOOKUP(AP54&AO54,huyen,3,FALSE)),"",VLOOKUP(AP54&AO54,huyen,3,FALSE)) | AS54: =IF(ISNA(VLOOKUP(AR54&AQ54,xa,3,FALSE)),"",VLOOKUP(AR54&AQ54,xa,3,FALSE)) -> #REF! | AU54: =IF(ISNA(VLOOKUP(AT54,tinh,2,FALSE)),"",VLOOKUP(AT54,tinh,2,FALSE)) | AW54: =IF(ISNA(VLOOKUP(AV54&AU54,huyen,3,FALSE)),"",VLOOKUP(AV54&AU54,huyen,3,FALSE)) | AY54: =IF(ISNA(VLOOKUP(AX54&AW54,xa,3,FALSE)),"",VLOOKUP(AX54&AW54,xa,3,FALSE)) -> #REF! | CB54: =IF(ISNA(VLOOKUP(CA54,tinh,2,FALSE)),"",VLOOKUP(CA54,tinh,2,FALSE)) | CD54: =IF(ISNA(VLOOKUP(CC54&CB54,huyen,3,FALSE)),"",VLOOKUP(CC54&CB54,huyen,3,FALSE))
E55: =IF(ISNA(VLOOKUP(D55,'Tổng hợp '!$B$25:$C$29,2,FALSE)),"",VLOOKUP(D55,'Tổng hợp '!$B$25:$C$29,2,FALSE)) | G55: =IF(ISNA(VLOOKUP(F55,phuong_an,2,FALSE)),"",VLOOKUP(F55,phuong_an,2,FALSE)) | H55: =+VLOOKUP(A55,[1]VT!$C:$I,7,0) -> #N/A | J55: =+VLOOKUP(A55,[1]VT!$C:$M,11,0) -> #N/A | AG55: =IF(ISNA(VLOOKUP(AF55,quocTich,2,FALSE)),"",VLOOKUP(AF55,quocTich,2,FALSE)) | AH55: =+VLOOKUP(A55,'[2]Thông tin công nhân'!$C:$P,14,0) -> #N/A | AI55: =IF(ISNA(VLOOKUP(AH55,danToc,2,FALSE)),"",VLOOKUP(AH55,danToc,2,FALSE)) | AK55: =IF(ISNA(VLOOKUP(AJ55,TinhBenhVien!A:B,2,FALSE)),"",VLOOKUP(AJ55,TinhBenhVien!A:B,2,FALSE)) | AM55: =IF(ISNA(VLOOKUP(AL55&AK55,benhVien,3,FALSE)),"",VLOOKUP(AL55&AK55,benhVien,3,FALSE)) -> 0 | AN55: ="tỉnh"&" "&VLOOKUP(A55,'[2]Thông tin công nhân'!$C:$AI,31,0) -> #N/A | AO55: =IF(ISNA(VLOOKUP(AN55,tinh,2,FALSE)),"",VLOOKUP(AN55,tinh,2,FALSE)) | AP55: ="xã"&" "&VLOOKUP(A55,'[2]Thông tin công nhân'!$C:$AI,33,0) -> #N/A | AQ55: =IF(ISNA(VLOOKUP(AP55&AO55,huyen,3,FALSE)),"",VLOOKUP(AP55&AO55,huyen,3,FALSE)) | AS55: =IF(ISNA(VLOOKUP(AR55&AQ55,xa,3,FALSE)),"",VLOOKUP(AR55&AQ55,xa,3,FALSE)) -> #REF! | AU55: =IF(ISNA(VLOOKUP(AT55,tinh,2,FALSE)),"",VLOOKUP(AT55,tinh,2,FALSE)) | AW55: =IF(ISNA(VLOOKUP(AV55&AU55,huyen,3,FALSE)),"",VLOOKUP(AV55&AU55,huyen,3,FALSE)) | AY55: =IF(ISNA(VLOOKUP(AX55&AW55,xa,3,FALSE)),"",VLOOKUP(AX55&AW55,xa,3,FALSE)) -> #REF! | CB55: =IF(ISNA(VLOOKUP(CA55,tinh,2,FALSE)),"",VLOOKUP(CA55,tinh,2,FALSE)) | CD55: =IF(ISNA(VLOOKUP(CC55&CB55,huyen,3,FALSE)),"",VLOOKUP(CC55&CB55,huyen,3,FALSE))
E56: =IF(ISNA(VLOOKUP(D56,'Tổng hợp '!$B$25:$C$29,2,FALSE)),"",VLOOKUP(D56,'Tổng hợp '!$B$25:$C$29,2,FALSE)) | G56: =IF(ISNA(VLOOKUP(F56,phuong_an,2,FALSE)),"",VLOOKUP(F56,phuong_an,2,FALSE)) | H56: =+VLOOKUP(A56,[1]VT!$C:$I,7,0) -> #N/A | J56: =+VLOOKUP(A56,[1]VT!$C:$M,11,0) -> #N/A | AG56: =IF(ISNA(VLOOKUP(AF56,quocTich,2,FALSE)),"",VLOOKUP(AF56,quocTich,2,FALSE)) | AH56: =+VLOOKUP(A56,'[2]Thông tin công nhân'!$C:$P,14,0) -> #N/A | AI56: =IF(ISNA(VLOOKUP(AH56,danToc,2,FALSE)),"",VLOOKUP(AH56,danToc,2,FALSE)) | AK56: =IF(ISNA(VLOOKUP(AJ56,TinhBenhVien!A:B,2,FALSE)),"",VLOOKUP(AJ56,TinhBenhVien!A:B,2,FALSE)) | AM56: =IF(ISNA(VLOOKUP(AL56&AK56,benhVien,3,FALSE)),"",VLOOKUP(AL56&AK56,benhVien,3,FALSE)) -> 0 | AN56: ="tỉnh"&" "&VLOOKUP(A56,'[2]Thông tin công nhân'!$C:$AI,31,0) -> #N/A | AO56: =IF(ISNA(VLOOKUP(AN56,tinh,2,FALSE)),"",VLOOKUP(AN56,tinh,2,FALSE)) | AP56: ="xã"&" "&VLOOKUP(A56,'[2]Thông tin công nhân'!$C:$AI,33,0) -> #N/A | AQ56: =IF(ISNA(VLOOKUP(AP56&AO56,huyen,3,FALSE)),"",VLOOKUP(AP56&AO56,huyen,3,FALSE)) | AS56: =IF(ISNA(VLOOKUP(AR56&AQ56,xa,3,FALSE)),"",VLOOKUP(AR56&AQ56,xa,3,FALSE)) -> #REF! | AU56: =IF(ISNA(VLOOKUP(AT56,tinh,2,FALSE)),"",VLOOKUP(AT56,tinh,2,FALSE)) | AW56: =IF(ISNA(VLOOKUP(AV56&AU56,huyen,3,FALSE)),"",VLOOKUP(AV56&AU56,huyen,3,FALSE)) | AY56: =IF(ISNA(VLOOKUP(AX56&AW56,xa,3,FALSE)),"",VLOOKUP(AX56&AW56,xa,3,FALSE)) -> #REF! | CB56: =IF(ISNA(VLOOKUP(CA56,tinh,2,FALSE)),"",VLOOKUP(CA56,tinh,2,FALSE)) | CD56: =IF(ISNA(VLOOKUP(CC56&CB56,huyen,3,FALSE)),"",VLOOKUP(CC56&CB56,huyen,3,FALSE))
E57: =IF(ISNA(VLOOKUP(D57,'Tổng hợp '!$B$25:$C$29,2,FALSE)),"",VLOOKUP(D57,'Tổng hợp '!$B$25:$C$29,2,FALSE)) | G57: =IF(ISNA(VLOOKUP(F57,phuong_an,2,FALSE)),"",VLOOKUP(F57,phuong_an,2,FALSE)) | H57: =+VLOOKUP(A57,[1]VT!$C:$I,7,0) -> #N/A | J57: =+VLOOKUP(A57,[1]VT!$C:$M,11,0) -> #N/A | AG57: =IF(ISNA(VLOOKUP(AF57,quocTich,2,FALSE)),"",VLOOKUP(AF57,quocTich,2,FALSE)) | AH57: =+VLOOKUP(A57,'[2]Thông tin công nhân'!$C:$P,14,0) -> #N/A | AI57: =IF(ISNA(VLOOKUP(AH57,danToc,2,FALSE)),"",VLOOKUP(AH57,danToc,2,FALSE)) | AK57: =IF(ISNA(VLOOKUP(AJ57,TinhBenhVien!A:B,2,FALSE)),"",VLOOKUP(AJ57,TinhBenhVien!A:B,2,FALSE)) | AM57: =IF(ISNA(VLOOKUP(AL57&AK57,benhVien,3,FALSE)),"",VLOOKUP(AL57&AK57,benhVien,3,FALSE)) -> 0 | AN57: ="tỉnh"&" "&VLOOKUP(A57,'[2]Thông tin công nhân'!$C:$AI,31,0) -> #N/A | AO57: =IF(ISNA(VLOOKUP(AN57,tinh,2,FALSE)),"",VLOOKUP(AN57,tinh,2,FALSE)) | AP57: ="xã"&" "&VLOOKUP(A57,'[2]Thông tin công nhân'!$C:$AI,33,0) -> #N/A | AQ57: =IF(ISNA(VLOOKUP(AP57&AO57,huyen,3,FALSE)),"",VLOOKUP(AP57&AO57,huyen,3,FALSE)) | AS57: =IF(ISNA(VLOOKUP(AR57&AQ57,xa,3,FALSE)),"",VLOOKUP(AR57&AQ57,xa,3,FALSE)) -> #REF! | AU57: =IF(ISNA(VLOOKUP(AT57,tinh,2,FALSE)),"",VLOOKUP(AT57,tinh,2,FALSE)) | AW57: =IF(ISNA(VLOOKUP(AV57&AU57,huyen,3,FALSE)),"",VLOOKUP(AV57&AU57,huyen,3,FALSE)) | AY57: =IF(ISNA(VLOOKUP(AX57&AW57,xa,3,FALSE)),"",VLOOKUP(AX57&AW57,xa,3,FALSE)) -> #REF! | CB57: =IF(ISNA(VLOOKUP(CA57,tinh,2,FALSE)),"",VLOOKUP(CA57,tinh,2,FALSE)) | CD57: =IF(ISNA(VLOOKUP(CC57&CB57,huyen,3,FALSE)),"",VLOOKUP(CC57&CB57,huyen,3,FALSE))
E58: =IF(ISNA(VLOOKUP(D58,'Tổng hợp '!$B$25:$C$29,2,FALSE)),"",VLOOKUP(D58,'Tổng hợp '!$B$25:$C$29,2,FALSE)) | G58: =IF(ISNA(VLOOKUP(F58,phuong_an,2,FALSE)),"",VLOOKUP(F58,phuong_an,2,FALSE)) | H58: =+VLOOKUP(A58,[1]VT!$C:$I,7,0) -> #N/A | J58: =+VLOOKUP(A58,[1]VT!$C:$M,11,0) -> #N/A | AG58: =IF(ISNA(VLOOKUP(AF58,quocTich,2,FALSE)),"",VLOOKUP(AF58,quocTich,2,FALSE)) | AH58: =+VLOOKUP(A58,'[2]Thông tin công nhân'!$C:$P,14,0) -> #N/A | AI58: =IF(ISNA(VLOOKUP(AH58,danToc,2,FALSE)),"",VLOOKUP(AH58,danToc,2,FALSE)) | AK58: =IF(ISNA(VLOOKUP(AJ58,TinhBenhVien!A:B,2,FALSE)),"",VLOOKUP(AJ58,TinhBenhVien!A:B,2,FALSE)) | AM58: =IF(ISNA(VLOOKUP(AL58&AK58,benhVien,3,FALSE)),"",VLOOKUP(AL58&AK58,benhVien,3,FALSE)) -> 0 | AN58: ="tỉnh"&" "&VLOOKUP(A58,'[2]Thông tin công nhân'!$C:$AI,31,0) -> #N/A | AO58: =IF(ISNA(VLOOKUP(AN58,tinh,2,FALSE)),"",VLOOKUP(AN58,tinh,2,FALSE)) | AP58: ="xã"&" "&VLOOKUP(A58,'[2]Thông tin công nhân'!$C:$AI,33,0) -> #N/A | AQ58: =IF(ISNA(VLOOKUP(AP58&AO58,huyen,3,FALSE)),"",VLOOKUP(AP58&AO58,huyen,3,FALSE)) | AS58: =IF(ISNA(VLOOKUP(AR58&AQ58,xa,3,FALSE)),"",VLOOKUP(AR58&AQ58,xa,3,FALSE)) -> #REF! | AU58: =IF(ISNA(VLOOKUP(AT58,tinh,2,FALSE)),"",VLOOKUP(AT58,tinh,2,FALSE)) | AW58: =IF(ISNA(VLOOKUP(AV58&AU58,huyen,3,FALSE)),"",VLOOKUP(AV58&AU58,huyen,3,FALSE)) | AY58: =IF(ISNA(VLOOKUP(AX58&AW58,xa,3,FALSE)),"",VLOOKUP(AX58&AW58,xa,3,FALSE)) -> #REF! | CB58: =IF(ISNA(VLOOKUP(CA58,tinh,2,FALSE)),"",VLOOKUP(CA58,tinh,2,FALSE)) | CD58: =IF(ISNA(VLOOKUP(CC58&CB58,huyen,3,FALSE)),"",VLOOKUP(CC58&CB58,huyen,3,FALSE))
E59: =IF(ISNA(VLOOKUP(D59,'Tổng hợp '!$B$25:$C$29,2,FALSE)),"",VLOOKUP(D59,'Tổng hợp '!$B$25:$C$29,2,FALSE)) | G59: =IF(ISNA(VLOOKUP(F59,phuong_an,2,FALSE)),"",VLOOKUP(F59,phuong_an,2,FALSE)) | H59: =+VLOOKUP(A59,[1]VT!$C:$I,7,0) -> #N/A | J59: =+VLOOKUP(A59,[1]VT!$C:$M,11,0) -> #N/A | AG59: =IF(ISNA(VLOOKUP(AF59,quocTich,2,FALSE)),"",VLOOKUP(AF59,quocTich,2,FALSE)) | AH59: =+VLOOKUP(A59,'[2]Thông tin công nhân'!$C:$P,14,0) -> #N/A | AI59: =IF(ISNA(VLOOKUP(AH59,danToc,2,FALSE)),"",VLOOKUP(AH59,danToc,2,FALSE)) | AK59: =IF(ISNA(VLOOKUP(AJ59,TinhBenhVien!A:B,2,FALSE)),"",VLOOKUP(AJ59,TinhBenhVien!A:B,2,FALSE)) | AM59: =IF(ISNA(VLOOKUP(AL59&AK59,benhVien,3,FALSE)),"",VLOOKUP(AL59&AK59,benhVien,3,FALSE)) -> 0 | AN59: ="tỉnh"&" "&VLOOKUP(A59,'[2]Thông tin công nhân'!$C:$AI,31,0) -> #N/A | AO59: =IF(ISNA(VLOOKUP(AN59,tinh,2,FALSE)),"",VLOOKUP(AN59,tinh,2,FALSE)) | AP59: ="xã"&" "&VLOOKUP(A59,'[2]Thông tin công nhân'!$C:$AI,33,0) -> #N/A | AQ59: =IF(ISNA(VLOOKUP(AP59&AO59,huyen,3,FALSE)),"",VLOOKUP(AP59&AO59,huyen,3,FALSE)) | AS59: =IF(ISNA(VLOOKUP(AR59&AQ59,xa,3,FALSE)),"",VLOOKUP(AR59&AQ59,xa,3,FALSE)) -> #REF! | AU59: =IF(ISNA(VLOOKUP(AT59,tinh,2,FALSE)),"",VLOOKUP(AT59,tinh,2,FALSE)) | AW59: =IF(ISNA(VLOOKUP(AV59&AU59,huyen,3,FALSE)),"",VLOOKUP(AV59&AU59,huyen,3,FALSE)) | AY59: =IF(ISNA(VLOOKUP(AX59&AW59,xa,3,FALSE)),"",VLOOKUP(AX59&AW59,xa,3,FALSE)) -> #REF! | CB59: =IF(ISNA(VLOOKUP(CA59,tinh,2,FALSE)),"",VLOOKUP(CA59,tinh,2,FALSE)) | CD59: =IF(ISNA(VLOOKUP(CC59&CB59,huyen,3,FALSE)),"",VLOOKUP(CC59&CB59,huyen,3,FALSE))
E60: =IF(ISNA(VLOOKUP(D60,'Tổng hợp '!$B$25:$C$29,2,FALSE)),"",VLOOKUP(D60,'Tổng hợp '!$B$25:$C$29,2,FALSE)) | G60: =IF(ISNA(VLOOKUP(F60,phuong_an,2,FALSE)),"",VLOOKUP(F60,phuong_an,2,FALSE)) | H60: =+VLOOKUP(A60,[1]VT!$C:$I,7,0) -> #N/A | J60: =+VLOOKUP(A60,[1]VT!$C:$M,11,0) -> #N/A | AG60: =IF(ISNA(VLOOKUP(AF60,quocTich,2,FALSE)),"",VLOOKUP(AF60,quocTich,2,FALSE)) | AH60: =+VLOOKUP(A60,'[2]Thông tin công nhân'!$C:$P,14,0) -> #N/A | AI60: =IF(ISNA(VLOOKUP(AH60,danToc,2,FALSE)),"",VLOOKUP(AH60,danToc,2,FALSE)) | AK60: =IF(ISNA(VLOOKUP(AJ60,TinhBenhVien!A:B,2,FALSE)),"",VLOOKUP(AJ60,TinhBenhVien!A:B,2,FALSE)) | AM60: =IF(ISNA(VLOOKUP(AL60&AK60,benhVien,3,FALSE)),"",VLOOKUP(AL60&AK60,benhVien,3,FALSE)) -> 0 | AN60: ="tỉnh"&" "&VLOOKUP(A60,'[2]Thông tin công nhân'!$C:$AI,31,0) -> #N/A | AO60: =IF(ISNA(VLOOKUP(AN60,tinh,2,FALSE)),"",VLOOKUP(AN60,tinh,2,FALSE)) | AP60: ="xã"&" "&VLOOKUP(A60,'[2]Thông tin công nhân'!$C:$AI,33,0) -> #N/A | AQ60: =IF(ISNA(VLOOKUP(AP60&AO60,huyen,3,FALSE)),"",VLOOKUP(AP60&AO60,huyen,3,FALSE)) | AS60: =IF(ISNA(VLOOKUP(AR60&AQ60,xa,3,FALSE)),"",VLOOKUP(AR60&AQ60,xa,3,FALSE)) -> #REF! | AU60: =IF(ISNA(VLOOKUP(AT60,tinh,2,FALSE)),"",VLOOKUP(AT60,tinh,2,FALSE)) | AW60: =IF(ISNA(VLOOKUP(AV60&AU60,huyen,3,FALSE)),"",VLOOKUP(AV60&AU60,huyen,3,FALSE)) | AY60: =IF(ISNA(VLOOKUP(AX60&AW60,xa,3,FALSE)),"",VLOOKUP(AX60&AW60,xa,3,FALSE)) -> #REF! | CB60: =IF(ISNA(VLOOKUP(CA60,tinh,2,FALSE)),"",VLOOKUP(CA60,tinh,2,FALSE)) | CD60: =IF(ISNA(VLOOKUP(CC60&CB60,huyen,3,FALSE)),"",VLOOKUP(CC60&CB60,huyen,3,FALSE))
E61: =IF(ISNA(VLOOKUP(D61,'Tổng hợp '!$B$25:$C$29,2,FALSE)),"",VLOOKUP(D61,'Tổng hợp '!$B$25:$C$29,2,FALSE)) | G61: =IF(ISNA(VLOOKUP(F61,phuong_an,2,FALSE)),"",VLOOKUP(F61,phuong_an,2,FALSE)) | H61: =+VLOOKUP(A61,[1]VT!$C:$I,7,0) -> #N/A | J61: =+VLOOKUP(A61,[1]VT!$C:$M,11,0) -> #N/A | AG61: =IF(ISNA(VLOOKUP(AF61,quocTich,2,FALSE)),"",VLOOKUP(AF61,quocTich,2,FALSE)) | AH61: =+VLOOKUP(A61,'[2]Thông tin công nhân'!$C:$P,14,0) -> #N/A | AI61: =IF(ISNA(VLOOKUP(AH61,danToc,2,FALSE)),"",VLOOKUP(AH61,danToc,2,FALSE)) | AK61: =IF(ISNA(VLOOKUP(AJ61,TinhBenhVien!A:B,2,FALSE)),"",VLOOKUP(AJ61,TinhBenhVien!A:B,2,FALSE)) | AM61: =IF(ISNA(VLOOKUP(AL61&AK61,benhVien,3,FALSE)),"",VLOOKUP(AL61&AK61,benhVien,3,FALSE)) -> 0 | AN61: ="tỉnh"&" "&VLOOKUP(A61,'[2]Thông tin công nhân'!$C:$AI,31,0) -> #N/A | AO61: =IF(ISNA(VLOOKUP(AN61,tinh,2,FALSE)),"",VLOOKUP(AN61,tinh,2,FALSE)) | AP61: ="xã"&" "&VLOOKUP(A61,'[2]Thông tin công nhân'!$C:$AI,33,0) -> #N/A | AQ61: =IF(ISNA(VLOOKUP(AP61&AO61,huyen,3,FALSE)),"",VLOOKUP(AP61&AO61,huyen,3,FALSE)) | AS61: =IF(ISNA(VLOOKUP(AR61&AQ61,xa,3,FALSE)),"",VLOOKUP(AR61&AQ61,xa,3,FALSE)) -> #REF! | AU61: =IF(ISNA(VLOOKUP(AT61,tinh,2,FALSE)),"",VLOOKUP(AT61,tinh,2,FALSE)) | AW61: =IF(ISNA(VLOOKUP(AV61&AU61,huyen,3,FALSE)),"",VLOOKUP(AV61&AU61,huyen,3,FALSE)) | AY61: =IF(ISNA(VLOOKUP(AX61&AW61,xa,3,FALSE)),"",VLOOKUP(AX61&AW61,xa,3,FALSE)) -> #REF! | CB61: =IF(ISNA(VLOOKUP(CA61,tinh,2,FALSE)),"",VLOOKUP(CA61,tinh,2,FALSE)) | CD61: =IF(ISNA(VLOOKUP(CC61&CB61,huyen,3,FALSE)),"",VLOOKUP(CC61&CB61,huyen,3,FALSE))
E62: =IF(ISNA(VLOOKUP(D62,'Tổng hợp '!$B$25:$C$29,2,FALSE)),"",VLOOKUP(D62,'Tổng hợp '!$B$25:$C$29,2,FALSE)) | G62: =IF(ISNA(VLOOKUP(F62,phuong_an,2,FALSE)),"",VLOOKUP(F62,phuong_an,2,FALSE)) | H62: =+VLOOKUP(A62,[1]VT!$C:$I,7,0) -> #N/A | J62: =+VLOOKUP(A62,[1]VT!$C:$M,11,0) -> #N/A | AG62: =IF(ISNA(VLOOKUP(AF62,quocTich,2,FALSE)),"",VLOOKUP(AF62,quocTich,2,FALSE)) | AH62: =+VLOOKUP(A62,'[2]Thông tin công nhân'!$C:$P,14,0) -> #N/A | AI62: =IF(ISNA(VLOOKUP(AH62,danToc,2,FALSE)),"",VLOOKUP(AH62,danToc,2,FALSE)) | AK62: =IF(ISNA(VLOOKUP(AJ62,TinhBenhVien!A:B,2,FALSE)),"",VLOOKUP(AJ62,TinhBenhVien!A:B,2,FALSE)) | AM62: =IF(ISNA(VLOOKUP(AL62&AK62,benhVien,3,FALSE)),"",VLOOKUP(AL62&AK62,benhVien,3,FALSE)) -> 0 | AN62: ="tỉnh"&" "&VLOOKUP(A62,'[2]Thông tin công nhân'!$C:$AI,31,0) -> #N/A | AO62: =IF(ISNA(VLOOKUP(AN62,tinh,2,FALSE)),"",VLOOKUP(AN62,tinh,2,FALSE)) | AP62: ="xã"&" "&VLOOKUP(A62,'[2]Thông tin công nhân'!$C:$AI,33,0) -> #N/A | AQ62: =IF(ISNA(VLOOKUP(AP62&AO62,huyen,3,FALSE)),"",VLOOKUP(AP62&AO62,huyen,3,FALSE)) | AS62: =IF(ISNA(VLOOKUP(AR62&AQ62,xa,3,FALSE)),"",VLOOKUP(AR62&AQ62,xa,3,FALSE)) -> #REF! | AU62: =IF(ISNA(VLOOKUP(AT62,tinh,2,FALSE)),"",VLOOKUP(AT62,tinh,2,FALSE)) | AW62: =IF(ISNA(VLOOKUP(AV62&AU62,huyen,3,FALSE)),"",VLOOKUP(AV62&AU62,huyen,3,FALSE)) | AY62: =IF(ISNA(VLOOKUP(AX62&AW62,xa,3,FALSE)),"",VLOOKUP(AX62&AW62,xa,3,FALSE)) -> #REF! | CB62: =IF(ISNA(VLOOKUP(CA62,tinh,2,FALSE)),"",VLOOKUP(CA62,tinh,2,FALSE)) | CD62: =IF(ISNA(VLOOKUP(CC62&CB62,huyen,3,FALSE)),"",VLOOKUP(CC62&CB62,huyen,3,FALSE))
... E983: =IF(ISNA(VLOOKUP(D983,'Tổng hợp '!$B$25:$C$29,2,FALSE)),"",VLOOKUP(D983,'Tổng hợp '!$B$25:$C$29,2,FALSE)) | G983: =IF(ISNA(VLOOKUP(F983,phuong_an,2,FALSE)),"",VLOOKUP(F983,phuong_an,2,FALSE)) | H983: =+VLOOKUP(A983,[1]VT!$C:$I,7,0) -> #N/A | J983: =+VLOOKUP(A983,[1]VT!$C:$M,11,0) -> #N/A | AG983: =IF(ISNA(VLOOKUP(AF983,quocTich,2,FALSE)),"",VLOOKUP(AF983,quocTich,2,FALSE)) | AH983: =+VLOOKUP(A983,'[2]Thông tin công nhân'!$C:$P,14,0) -> #N/A | AI983: =IF(ISNA(VLOOKUP(AH983,danToc,2,FALSE)),"",VLOOKUP(AH983,danToc,2,FALSE)) | AK983: =IF(ISNA(VLOOKUP(AJ983,TinhBenhVien!A:B,2,FALSE)),"",VLOOKUP(AJ983,TinhBenhVien!A:B,2,FALSE)) | AM983: =IF(ISNA(VLOOKUP(AL983&AK983,benhVien,3,FALSE)),"",VLOOKUP(AL983&AK983,benhVien,3,FALSE)) -> 0 | AN983: ="tỉnh"&" "&VLOOKUP(A983,'[2]Thông tin công nhân'!$C:$AI,31,0) -> #N/A | AO983: =IF(ISNA(VLOOKUP(AN983,tinh,2,FALSE)),"",VLOOKUP(AN983,tinh,2,FALSE)) | AP983: ="xã"&" "&VLOOKUP(A983,'[2]Thông tin công nhân'!$C:$AI,33,0) -> #N/A | AQ983: =IF(ISNA(VLOOKUP(AP983&AO983,huyen,3,FALSE)),"",VLOOKUP(AP983&AO983,huyen,3,FALSE)) | AS983: =IF(ISNA(VLOOKUP(AR983&AQ983,xa,3,FALSE)),"",VLOOKUP(AR983&AQ983,xa,3,FALSE)) -> #REF! | AU983: =IF(ISNA(VLOOKUP(AT983,tinh,2,FALSE)),"",VLOOKUP(AT983,tinh,2,FALSE)) | AW983: =IF(ISNA(VLOOKUP(AV983&AU983,huyen,3,FALSE)),"",VLOOKUP(AV983&AU983,huyen,3,FALSE)) | AY983: =IF(ISNA(VLOOKUP(AX983&AW983,xa,3,FALSE)),"",VLOOKUP(AX983&AW983,xa,3,FALSE)) -> #REF! | CB983: =IF(ISNA(VLOOKUP(CA983,tinh,2,FALSE)),"",VLOOKUP(CA983,tinh,2,FALSE)) | CD983: =IF(ISNA(VLOOKUP(CC983&CB983,huyen,3,FALSE)),"",VLOOKUP(CC983&CB983,huyen,3,FALSE))

Sheet Phụ lục
B1: THÔNG TIN THÀNH VIÊN (Bao gồm cả người tham gia và chủ hộ)
A2: ID Lao động lấy ở Sheet Dữ Liệu | B2: Họ tên Thành viên | C2: Mã số BHXH | D2: Ngày sinh (tháng/năm hoặc năm sinh) | E2: Giới tính | F2: Tỉnh khai sinh | G2: Mã tỉnh khai sinh | H2: Xã khai sinh | I2: Mã xã khai sinh | J2: Xã khai sinh | K2: Mã xã khai sinh | L2: Tên Thôn/Xóm | M2: Mối quan hệ | N2: Mã quan hệ | O2: Số CMND của thành viên | P2: Ghi chú | Q2: Người tham gia (0: Không 1: Có) | R2: Số điện thoại | S2: Loại giấy tờ | T2: Số giấy tờ | U2: Quốc tịch | V2: Dân tộc | W2: Tỉnh hộ khẩu | X2: Mã tỉnh hộ khẩu | Y2: Xã hộ khẩu | Z2: Mã xã khai sinh | AA2: Xã hộ khẩu | AB2: Mã xã khai sinh | AC2: Mã số hộ gia đình | AD2: Địa chỉ hộ khẩu | AE2: Địa chỉ đăng ký khai sinh | AF2: Địa chỉ thường trú | AG2: Tỉnh thường trú | AH2: Mã tỉnh thường trú | AI2: Xã thường trú | AJ2: Mã xã thường trú | AK2: Xã thường trú | AL2: Mã xã thường trú | AM2: Số CCCD/ĐDCN chủ hộ
A3: STT | B3: HoTen | C3: MasoBHXH | D3: NgaySinh | E3: GioiTinh | F3: TenTinhKS | G3: Matinh_KS | H3: TenXaKS | I3: Maxa_KS | L3: MaThon | M3: TenMoiQuanHe | N3: MoiQuanHe | O3: CMND | P3: Ghichu | Q3: NguoiThamGia | R3: DienThoai | S3: LoaiGiayTo | T3: SoGiayTo | U3: QuocTich | V3: DanToc | W3: TenTinh | X3: Matinh | Y3: TenXa | Z3: Maxa | AC3: Maso_HoGiadinh | AD3: Diachi_HK | AE3: DiachiDK_KS | AF3: Diachi_TT_CH | AG3: TenTinh_TT_CH | AH3: Tinh_TT_CH | AI3: TenXa_TT_CH | AJ3: Xa_TT_CH | AM3: SoCCCD_CH
A4: 1 | B4: Bùi Văn A | C4: 1234567890 | D4: 1990 | E4: 1 | F4: Thành phố Hà Nội | G4: =IF(ISNA(VLOOKUP(F4,tinh,2,FALSE)),"",VLOOKUP(F4,tinh,2,FALSE)) -> 01 | H4: Quận Hoàn Kiếm | I4: =IF(ISNA(VLOOKUP(H4&G4,huyen,3,FALSE)),"",VLOOKUP(H4&G4,huyen,3,FALSE)) | J4: Xã Trường Hà | K4: =IF(ISNA(VLOOKUP(J4&I4,xa,3,FALSE)),"",VLOOKUP(J4&I4,xa,3,FALSE)) -> #REF! | M4: Chủ hộ | N4: =IF(ISNA(VLOOKUP(M4,ma_mqh,2,FALSE)),"",VLOOKUP(M4,ma_mqh,2,FALSE)) -> 00 | Q4: 1 | S4: 1 | U4: VN | V4: 01 | W4: Tỉnh Tuyên Quang | X4: =IF(ISNA(VLOOKUP(W4,tinh,2,FALSE)),"",VLOOKUP(W4,tinh,2,FALSE)) -> 08 | Y4: Huyện Na Hang | Z4: =IF(ISNA(VLOOKUP(Y4&X4,huyen,3,FALSE)),"",VLOOKUP(Y4&X4,huyen,3,FALSE)) | AA4: Xã Thượng Giáp | AB4: =IF(ISNA(VLOOKUP(AA4&Z4,xa,3,FALSE)),"",VLOOKUP(AA4&Z4,xa,3,FALSE)) -> #REF! | AC4: 11313232 | AD4: Tòa nhà Internet | AE4: Tòa nhà Internet | AF4: Tòa nhà Internet | AG4: Tỉnh Tuyên Quang | AH4: =IF(ISNA(VLOOKUP(AG4,tinh,2,FALSE)),"",VLOOKUP(AG4,tinh,2,FALSE)) -> 08 | AI4: Huyện Na Hang | AJ4: =IF(ISNA(VLOOKUP(AI4&AH4,huyen,3,FALSE)),"",VLOOKUP(AI4&AH4,huyen,3,FALSE)) | AK4: Xã Thượng Giáp | AL4: =IF(ISNA(VLOOKUP(AK4&AJ4,xa,3,FALSE)),"",VLOOKUP(AK4&AJ4,xa,3,FALSE)) -> #REF! | AM4: 001298765432 | AO4: 250128 | AP4: 25107483SW | AQ4: 250128
G5: =IF(ISNA(VLOOKUP(F5,tinh,2,FALSE)),"",VLOOKUP(F5,tinh,2,FALSE)) | I5: =IF(ISNA(VLOOKUP(H5&G5,huyen,3,FALSE)),"",VLOOKUP(H5&G5,huyen,3,FALSE)) | K5: =IF(ISNA(VLOOKUP(J5&I5,xa,3,FALSE)),"",VLOOKUP(J5&I5,xa,3,FALSE)) -> #REF! | N5: =IF(ISNA(VLOOKUP(M5,ma_mqh,2,FALSE)),"",VLOOKUP(M5,ma_mqh,2,FALSE)) | X5: =IF(ISNA(VLOOKUP(W5,tinh,2,FALSE)),"",VLOOKUP(W5,tinh,2,FALSE)) | Z5: =IF(ISNA(VLOOKUP(Y5&X5,huyen,3,FALSE)),"",VLOOKUP(Y5&X5,huyen,3,FALSE)) | AB5: =IF(ISNA(VLOOKUP(AA5&Z5,xa,3,FALSE)),"",VLOOKUP(AA5&Z5,xa,3,FALSE)) -> #REF! | AH5: =IF(ISNA(VLOOKUP(AG5,tinh,2,FALSE)),"",VLOOKUP(AG5,tinh,2,FALSE)) | AJ5: =IF(ISNA(VLOOKUP(AI5&AH5,huyen,3,FALSE)),"",VLOOKUP(AI5&AH5,huyen,3,FALSE)) | AL5: =IF(ISNA(VLOOKUP(AK5&AJ5,xa,3,FALSE)),"",VLOOKUP(AK5&AJ5,xa,3,FALSE)) -> #REF! | AO5: 250129 | AP5: 25107484QW | AQ5: 250129
G6: =IF(ISNA(VLOOKUP(F6,tinh,2,FALSE)),"",VLOOKUP(F6,tinh,2,FALSE)) | I6: =IF(ISNA(VLOOKUP(H6&G6,huyen,3,FALSE)),"",VLOOKUP(H6&G6,huyen,3,FALSE)) | K6: =IF(ISNA(VLOOKUP(J6&I6,xa,3,FALSE)),"",VLOOKUP(J6&I6,xa,3,FALSE)) -> #REF! | N6: =IF(ISNA(VLOOKUP(M6,ma_mqh,2,FALSE)),"",VLOOKUP(M6,ma_mqh,2,FALSE)) | X6: =IF(ISNA(VLOOKUP(W6,tinh,2,FALSE)),"",VLOOKUP(W6,tinh,2,FALSE)) | Z6: =IF(ISNA(VLOOKUP(Y6&X6,huyen,3,FALSE)),"",VLOOKUP(Y6&X6,huyen,3,FALSE)) | AB6: =IF(ISNA(VLOOKUP(AA6&Z6,xa,3,FALSE)),"",VLOOKUP(AA6&Z6,xa,3,FALSE)) -> #REF! | AH6: =IF(ISNA(VLOOKUP(AG6,tinh,2,FALSE)),"",VLOOKUP(AG6,tinh,2,FALSE)) | AJ6: =IF(ISNA(VLOOKUP(AI6&AH6,huyen,3,FALSE)),"",VLOOKUP(AI6&AH6,huyen,3,FALSE)) | AL6: =IF(ISNA(VLOOKUP(AK6&AJ6,xa,3,FALSE)),"",VLOOKUP(AK6&AJ6,xa,3,FALSE)) -> #REF! | AO6: 250130 | AP6: 25107485QW | AQ6: 250130
G7: =IF(ISNA(VLOOKUP(F7,tinh,2,FALSE)),"",VLOOKUP(F7,tinh,2,FALSE)) | I7: =IF(ISNA(VLOOKUP(H7&G7,huyen,3,FALSE)),"",VLOOKUP(H7&G7,huyen,3,FALSE)) | K7: =IF(ISNA(VLOOKUP(J7&I7,xa,3,FALSE)),"",VLOOKUP(J7&I7,xa,3,FALSE)) -> #REF! | N7: =IF(ISNA(VLOOKUP(M7,ma_mqh,2,FALSE)),"",VLOOKUP(M7,ma_mqh,2,FALSE)) | X7: =IF(ISNA(VLOOKUP(W7,tinh,2,FALSE)),"",VLOOKUP(W7,tinh,2,FALSE)) | Z7: =IF(ISNA(VLOOKUP(Y7&X7,huyen,3,FALSE)),"",VLOOKUP(Y7&X7,huyen,3,FALSE)) | AB7: =IF(ISNA(VLOOKUP(AA7&Z7,xa,3,FALSE)),"",VLOOKUP(AA7&Z7,xa,3,FALSE)) -> #REF! | AH7: =IF(ISNA(VLOOKUP(AG7,tinh,2,FALSE)),"",VLOOKUP(AG7,tinh,2,FALSE)) | AJ7: =IF(ISNA(VLOOKUP(AI7&AH7,huyen,3,FALSE)),"",VLOOKUP(AI7&AH7,huyen,3,FALSE)) | AL7: =IF(ISNA(VLOOKUP(AK7&AJ7,xa,3,FALSE)),"",VLOOKUP(AK7&AJ7,xa,3,FALSE)) -> #REF! | AO7: 250131 | AP7: 25107489PW | AQ7: 250131
G8: =IF(ISNA(VLOOKUP(F8,tinh,2,FALSE)),"",VLOOKUP(F8,tinh,2,FALSE)) | I8: =IF(ISNA(VLOOKUP(H8&G8,huyen,3,FALSE)),"",VLOOKUP(H8&G8,huyen,3,FALSE)) | K8: =IF(ISNA(VLOOKUP(J8&I8,xa,3,FALSE)),"",VLOOKUP(J8&I8,xa,3,FALSE)) -> #REF! | N8: =IF(ISNA(VLOOKUP(M8,ma_mqh,2,FALSE)),"",VLOOKUP(M8,ma_mqh,2,FALSE)) | X8: =IF(ISNA(VLOOKUP(W8,tinh,2,FALSE)),"",VLOOKUP(W8,tinh,2,FALSE)) | Z8: =IF(ISNA(VLOOKUP(Y8&X8,huyen,3,FALSE)),"",VLOOKUP(Y8&X8,huyen,3,FALSE)) | AB8: =IF(ISNA(VLOOKUP(AA8&Z8,xa,3,FALSE)),"",VLOOKUP(AA8&Z8,xa,3,FALSE)) -> #REF! | AH8: =IF(ISNA(VLOOKUP(AG8,tinh,2,FALSE)),"",VLOOKUP(AG8,tinh,2,FALSE)) | AJ8: =IF(ISNA(VLOOKUP(AI8&AH8,huyen,3,FALSE)),"",VLOOKUP(AI8&AH8,huyen,3,FALSE)) | AL8: =IF(ISNA(VLOOKUP(AK8&AJ8,xa,3,FALSE)),"",VLOOKUP(AK8&AJ8,xa,3,FALSE)) -> #REF! | AO8: 250132 | AP8: 25107490PW | AQ8: 250132
G9: =IF(ISNA(VLOOKUP(F9,tinh,2,FALSE)),"",VLOOKUP(F9,tinh,2,FALSE)) | I9: =IF(ISNA(VLOOKUP(H9&G9,huyen,3,FALSE)),"",VLOOKUP(H9&G9,huyen,3,FALSE)) | K9: =IF(ISNA(VLOOKUP(J9&I9,xa,3,FALSE)),"",VLOOKUP(J9&I9,xa,3,FALSE)) -> #REF! | N9: =IF(ISNA(VLOOKUP(M9,ma_mqh,2,FALSE)),"",VLOOKUP(M9,ma_mqh,2,FALSE)) | X9: =IF(ISNA(VLOOKUP(W9,tinh,2,FALSE)),"",VLOOKUP(W9,tinh,2,FALSE)) | Z9: =IF(ISNA(VLOOKUP(Y9&X9,huyen,3,FALSE)),"",VLOOKUP(Y9&X9,huyen,3,FALSE)) | AB9: =IF(ISNA(VLOOKUP(AA9&Z9,xa,3,FALSE)),"",VLOOKUP(AA9&Z9,xa,3,FALSE)) -> #REF! | AH9: =IF(ISNA(VLOOKUP(AG9,tinh,2,FALSE)),"",VLOOKUP(AG9,tinh,2,FALSE)) | AJ9: =IF(ISNA(VLOOKUP(AI9&AH9,huyen,3,FALSE)),"",VLOOKUP(AI9&AH9,huyen,3,FALSE)) | AL9: =IF(ISNA(VLOOKUP(AK9&AJ9,xa,3,FALSE)),"",VLOOKUP(AK9&AJ9,xa,3,FALSE)) -> #REF! | AO9: 250133 | AP9: 25107491QW | AQ9: 250133
G10: =IF(ISNA(VLOOKUP(F10,tinh,2,FALSE)),"",VLOOKUP(F10,tinh,2,FALSE)) | I10: =IF(ISNA(VLOOKUP(H10&G10,huyen,3,FALSE)),"",VLOOKUP(H10&G10,huyen,3,FALSE)) | K10: =IF(ISNA(VLOOKUP(J10&I10,xa,3,FALSE)),"",VLOOKUP(J10&I10,xa,3,FALSE)) -> #REF! | N10: =IF(ISNA(VLOOKUP(M10,ma_mqh,2,FALSE)),"",VLOOKUP(M10,ma_mqh,2,FALSE)) | X10: =IF(ISNA(VLOOKUP(W10,tinh,2,FALSE)),"",VLOOKUP(W10,tinh,2,FALSE)) | Z10: =IF(ISNA(VLOOKUP(Y10&X10,huyen,3,FALSE)),"",VLOOKUP(Y10&X10,huyen,3,FALSE)) | AB10: =IF(ISNA(VLOOKUP(AA10&Z10,xa,3,FALSE)),"",VLOOKUP(AA10&Z10,xa,3,FALSE)) -> #REF! | AH10: =IF(ISNA(VLOOKUP(AG10,tinh,2,FALSE)),"",VLOOKUP(AG10,tinh,2,FALSE)) | AJ10: =IF(ISNA(VLOOKUP(AI10&AH10,huyen,3,FALSE)),"",VLOOKUP(AI10&AH10,huyen,3,FALSE)) | AL10: =IF(ISNA(VLOOKUP(AK10&AJ10,xa,3,FALSE)),"",VLOOKUP(AK10&AJ10,xa,3,FALSE)) -> #REF! | AO10: 250134 | AP10: 25107492PW | AQ10: 250134
G11: =IF(ISNA(VLOOKUP(F11,tinh,2,FALSE)),"",VLOOKUP(F11,tinh,2,FALSE)) | I11: =IF(ISNA(VLOOKUP(H11&G11,huyen,3,FALSE)),"",VLOOKUP(H11&G11,huyen,3,FALSE)) | K11: =IF(ISNA(VLOOKUP(J11&I11,xa,3,FALSE)),"",VLOOKUP(J11&I11,xa,3,FALSE)) -> #REF! | N11: =IF(ISNA(VLOOKUP(M11,ma_mqh,2,FALSE)),"",VLOOKUP(M11,ma_mqh,2,FALSE)) | X11: =IF(ISNA(VLOOKUP(W11,tinh,2,FALSE)),"",VLOOKUP(W11,tinh,2,FALSE)) | Z11: =IF(ISNA(VLOOKUP(Y11&X11,huyen,3,FALSE)),"",VLOOKUP(Y11&X11,huyen,3,FALSE)) | AB11: =IF(ISNA(VLOOKUP(AA11&Z11,xa,3,FALSE)),"",VLOOKUP(AA11&Z11,xa,3,FALSE)) -> #REF! | AH11: =IF(ISNA(VLOOKUP(AG11,tinh,2,FALSE)),"",VLOOKUP(AG11,tinh,2,FALSE)) | AJ11: =IF(ISNA(VLOOKUP(AI11&AH11,huyen,3,FALSE)),"",VLOOKUP(AI11&AH11,huyen,3,FALSE)) | AL11: =IF(ISNA(VLOOKUP(AK11&AJ11,xa,3,FALSE)),"",VLOOKUP(AK11&AJ11,xa,3,FALSE)) -> #REF! | AO11: 250135 | AP11: 25107493SW | AQ11: 250135
G12: =IF(ISNA(VLOOKUP(F12,tinh,2,FALSE)),"",VLOOKUP(F12,tinh,2,FALSE)) | I12: =IF(ISNA(VLOOKUP(H12&G12,huyen,3,FALSE)),"",VLOOKUP(H12&G12,huyen,3,FALSE)) | K12: =IF(ISNA(VLOOKUP(J12&I12,xa,3,FALSE)),"",VLOOKUP(J12&I12,xa,3,FALSE)) -> #REF! | N12: =IF(ISNA(VLOOKUP(M12,ma_mqh,2,FALSE)),"",VLOOKUP(M12,ma_mqh,2,FALSE)) | X12: =IF(ISNA(VLOOKUP(W12,tinh,2,FALSE)),"",VLOOKUP(W12,tinh,2,FALSE)) | Z12: =IF(ISNA(VLOOKUP(Y12&X12,huyen,3,FALSE)),"",VLOOKUP(Y12&X12,huyen,3,FALSE)) | AB12: =IF(ISNA(VLOOKUP(AA12&Z12,xa,3,FALSE)),"",VLOOKUP(AA12&Z12,xa,3,FALSE)) -> #REF! | AH12: =IF(ISNA(VLOOKUP(AG12,tinh,2,FALSE)),"",VLOOKUP(AG12,tinh,2,FALSE)) | AJ12: =IF(ISNA(VLOOKUP(AI12&AH12,huyen,3,FALSE)),"",VLOOKUP(AI12&AH12,huyen,3,FALSE)) | AL12: =IF(ISNA(VLOOKUP(AK12&AJ12,xa,3,FALSE)),"",VLOOKUP(AK12&AJ12,xa,3,FALSE)) -> #REF! | AO12: 250136 | AP12: 25107494PW | AQ12: 250136
G13: =IF(ISNA(VLOOKUP(F13,tinh,2,FALSE)),"",VLOOKUP(F13,tinh,2,FALSE)) | I13: =IF(ISNA(VLOOKUP(H13&G13,huyen,3,FALSE)),"",VLOOKUP(H13&G13,huyen,3,FALSE)) | K13: =IF(ISNA(VLOOKUP(J13&I13,xa,3,FALSE)),"",VLOOKUP(J13&I13,xa,3,FALSE)) -> #REF! | N13: =IF(ISNA(VLOOKUP(M13,ma_mqh,2,FALSE)),"",VLOOKUP(M13,ma_mqh,2,FALSE)) | X13: =IF(ISNA(VLOOKUP(W13,tinh,2,FALSE)),"",VLOOKUP(W13,tinh,2,FALSE)) | Z13: =IF(ISNA(VLOOKUP(Y13&X13,huyen,3,FALSE)),"",VLOOKUP(Y13&X13,huyen,3,FALSE)) | AB13: =IF(ISNA(VLOOKUP(AA13&Z13,xa,3,FALSE)),"",VLOOKUP(AA13&Z13,xa,3,FALSE)) -> #REF! | AH13: =IF(ISNA(VLOOKUP(AG13,tinh,2,FALSE)),"",VLOOKUP(AG13,tinh,2,FALSE)) | AJ13: =IF(ISNA(VLOOKUP(AI13&AH13,huyen,3,FALSE)),"",VLOOKUP(AI13&AH13,huyen,3,FALSE)) | AL13: =IF(ISNA(VLOOKUP(AK13&AJ13,xa,3,FALSE)),"",VLOOKUP(AK13&AJ13,xa,3,FALSE)) -> #REF! | AO13: 250137 | AP13: 25107495SW | AQ13: 250137
G14: =IF(ISNA(VLOOKUP(F14,tinh,2,FALSE)),"",VLOOKUP(F14,tinh,2,FALSE)) | I14: =IF(ISNA(VLOOKUP(H14&G14,huyen,3,FALSE)),"",VLOOKUP(H14&G14,huyen,3,FALSE)) | K14: =IF(ISNA(VLOOKUP(J14&I14,xa,3,FALSE)),"",VLOOKUP(J14&I14,xa,3,FALSE)) -> #REF! | N14: =IF(ISNA(VLOOKUP(M14,ma_mqh,2,FALSE)),"",VLOOKUP(M14,ma_mqh,2,FALSE)) | X14: =IF(ISNA(VLOOKUP(W14,tinh,2,FALSE)),"",VLOOKUP(W14,tinh,2,FALSE)) | Z14: =IF(ISNA(VLOOKUP(Y14&X14,huyen,3,FALSE)),"",VLOOKUP(Y14&X14,huyen,3,FALSE)) | AB14: =IF(ISNA(VLOOKUP(AA14&Z14,xa,3,FALSE)),"",VLOOKUP(AA14&Z14,xa,3,FALSE)) -> #REF! | AH14: =IF(ISNA(VLOOKUP(AG14,tinh,2,FALSE)),"",VLOOKUP(AG14,tinh,2,FALSE)) | AJ14: =IF(ISNA(VLOOKUP(AI14&AH14,huyen,3,FALSE)),"",VLOOKUP(AI14&AH14,huyen,3,FALSE)) | AL14: =IF(ISNA(VLOOKUP(AK14&AJ14,xa,3,FALSE)),"",VLOOKUP(AK14&AJ14,xa,3,FALSE)) -> #REF! | AO14: 250138 | AP14: 25107497PW | AQ14: 250138
G15: =IF(ISNA(VLOOKUP(F15,tinh,2,FALSE)),"",VLOOKUP(F15,tinh,2,FALSE)) | I15: =IF(ISNA(VLOOKUP(H15&G15,huyen,3,FALSE)),"",VLOOKUP(H15&G15,huyen,3,FALSE)) | K15: =IF(ISNA(VLOOKUP(J15&I15,xa,3,FALSE)),"",VLOOKUP(J15&I15,xa,3,FALSE)) -> #REF! | N15: =IF(ISNA(VLOOKUP(M15,ma_mqh,2,FALSE)),"",VLOOKUP(M15,ma_mqh,2,FALSE)) | X15: =IF(ISNA(VLOOKUP(W15,tinh,2,FALSE)),"",VLOOKUP(W15,tinh,2,FALSE)) | Z15: =IF(ISNA(VLOOKUP(Y15&X15,huyen,3,FALSE)),"",VLOOKUP(Y15&X15,huyen,3,FALSE)) | AB15: =IF(ISNA(VLOOKUP(AA15&Z15,xa,3,FALSE)),"",VLOOKUP(AA15&Z15,xa,3,FALSE)) -> #REF! | AH15: =IF(ISNA(VLOOKUP(AG15,tinh,2,FALSE)),"",VLOOKUP(AG15,tinh,2,FALSE)) | AJ15: =IF(ISNA(VLOOKUP(AI15&AH15,huyen,3,FALSE)),"",VLOOKUP(AI15&AH15,huyen,3,FALSE)) | AL15: =IF(ISNA(VLOOKUP(AK15&AJ15,xa,3,FALSE)),"",VLOOKUP(AK15&AJ15,xa,3,FALSE)) -> #REF! | AO15: 250139 | AP15: 25107498PW | AQ15: 250139
G16: =IF(ISNA(VLOOKUP(F16,tinh,2,FALSE)),"",VLOOKUP(F16,tinh,2,FALSE)) | I16: =IF(ISNA(VLOOKUP(H16&G16,huyen,3,FALSE)),"",VLOOKUP(H16&G16,huyen,3,FALSE)) | K16: =IF(ISNA(VLOOKUP(J16&I16,xa,3,FALSE)),"",VLOOKUP(J16&I16,xa,3,FALSE)) -> #REF! | N16: =IF(ISNA(VLOOKUP(M16,ma_mqh,2,FALSE)),"",VLOOKUP(M16,ma_mqh,2,FALSE)) | X16: =IF(ISNA(VLOOKUP(W16,tinh,2,FALSE)),"",VLOOKUP(W16,tinh,2,FALSE)) | Z16: =IF(ISNA(VLOOKUP(Y16&X16,huyen,3,FALSE)),"",VLOOKUP(Y16&X16,huyen,3,FALSE)) | AB16: =IF(ISNA(VLOOKUP(AA16&Z16,xa,3,FALSE)),"",VLOOKUP(AA16&Z16,xa,3,FALSE)) -> #REF! | AH16: =IF(ISNA(VLOOKUP(AG16,tinh,2,FALSE)),"",VLOOKUP(AG16,tinh,2,FALSE)) | AJ16: =IF(ISNA(VLOOKUP(AI16&AH16,huyen,3,FALSE)),"",VLOOKUP(AI16&AH16,huyen,3,FALSE)) | AL16: =IF(ISNA(VLOOKUP(AK16&AJ16,xa,3,FALSE)),"",VLOOKUP(AK16&AJ16,xa,3,FALSE)) -> #REF! | AO16: 250140 | AP16: 25107500SW | AQ16: 250140
... G22: =IF(ISNA(VLOOKUP(F22,tinh,2,FALSE)),"",VLOOKUP(F22,tinh,2,FALSE)) | I22: =IF(ISNA(VLOOKUP(H22&G22,huyen,3,FALSE)),"",VLOOKUP(H22&G22,huyen,3,FALSE)) | K22: =IF(ISNA(VLOOKUP(J22&I22,xa,3,FALSE)),"",VLOOKUP(J22&I22,xa,3,FALSE)) -> #REF! | N22: =IF(ISNA(VLOOKUP(M22,ma_mqh,2,FALSE)),"",VLOOKUP(M22,ma_mqh,2,FALSE)) | X22: =IF(ISNA(VLOOKUP(W22,tinh,2,FALSE)),"",VLOOKUP(W22,tinh,2,FALSE)) | Z22: =IF(ISNA(VLOOKUP(Y22&X22,huyen,3,FALSE)),"",VLOOKUP(Y22&X22,huyen,3,FALSE)) | AB22: =IF(ISNA(VLOOKUP(AA22&Z22,xa,3,FALSE)),"",VLOOKUP(AA22&Z22,xa,3,FALSE)) -> #REF! | AH22: =IF(ISNA(VLOOKUP(AG22,tinh,2,FALSE)),"",VLOOKUP(AG22,tinh,2,FALSE)) | AJ22: =IF(ISNA(VLOOKUP(AI22&AH22,huyen,3,FALSE)),"",VLOOKUP(AI22&AH22,huyen,3,FALSE)) | AL22: =IF(ISNA(VLOOKUP(AK22&AJ22,xa,3,FALSE)),"",VLOOKUP(AK22&AJ22,xa,3,FALSE)) -> #REF! | AO22: 250146 | AP22: 25107509QW | AQ22: 250146
G23: =IF(ISNA(VLOOKUP(F23,tinh,2,FALSE)),"",VLOOKUP(F23,tinh,2,FALSE)) | I23: =IF(ISNA(VLOOKUP(H23&G23,huyen,3,FALSE)),"",VLOOKUP(H23&G23,huyen,3,FALSE)) | K23: =IF(ISNA(VLOOKUP(J23&I23,xa,3,FALSE)),"",VLOOKUP(J23&I23,xa,3,FALSE)) -> #REF! | N23: =IF(ISNA(VLOOKUP(M23,ma_mqh,2,FALSE)),"",VLOOKUP(M23,ma_mqh,2,FALSE)) | X23: =IF(ISNA(VLOOKUP(W23,tinh,2,FALSE)),"",VLOOKUP(W23,tinh,2,FALSE)) | Z23: =IF(ISNA(VLOOKUP(Y23&X23,huyen,3,FALSE)),"",VLOOKUP(Y23&X23,huyen,3,FALSE)) | AB23: =IF(ISNA(VLOOKUP(AA23&Z23,xa,3,FALSE)),"",VLOOKUP(AA23&Z23,xa,3,FALSE)) -> #REF! | AH23: =IF(ISNA(VLOOKUP(AG23,tinh,2,FALSE)),"",VLOOKUP(AG23,tinh,2,FALSE)) | AJ23: =IF(ISNA(VLOOKUP(AI23&AH23,huyen,3,FALSE)),"",VLOOKUP(AI23&AH23,huyen,3,FALSE)) | AL23: =IF(ISNA(VLOOKUP(AK23&AJ23,xa,3,FALSE)),"",VLOOKUP(AK23&AJ23,xa,3,FALSE)) -> #REF!
G24: =IF(ISNA(VLOOKUP(F24,tinh,2,FALSE)),"",VLOOKUP(F24,tinh,2,FALSE)) | I24: =IF(ISNA(VLOOKUP(H24&G24,huyen,3,FALSE)),"",VLOOKUP(H24&G24,huyen,3,FALSE)) | K24: =IF(ISNA(VLOOKUP(J24&I24,xa,3,FALSE)),"",VLOOKUP(J24&I24,xa,3,FALSE)) -> #REF! | N24: =IF(ISNA(VLOOKUP(M24,ma_mqh,2,FALSE)),"",VLOOKUP(M24,ma_mqh,2,FALSE)) | X24: =IF(ISNA(VLOOKUP(W24,tinh,2,FALSE)),"",VLOOKUP(W24,tinh,2,FALSE)) | Z24: =IF(ISNA(VLOOKUP(Y24&X24,huyen,3,FALSE)),"",VLOOKUP(Y24&X24,huyen,3,FALSE)) | AB24: =IF(ISNA(VLOOKUP(AA24&Z24,xa,3,FALSE)),"",VLOOKUP(AA24&Z24,xa,3,FALSE)) -> #REF! | AH24: =IF(ISNA(VLOOKUP(AG24,tinh,2,FALSE)),"",VLOOKUP(AG24,tinh,2,FALSE)) | AJ24: =IF(ISNA(VLOOKUP(AI24&AH24,huyen,3,FALSE)),"",VLOOKUP(AI24&AH24,huyen,3,FALSE)) | AL24: =IF(ISNA(VLOOKUP(AK24&AJ24,xa,3,FALSE)),"",VLOOKUP(AK24&AJ24,xa,3,FALSE)) -> #REF!
G25: =IF(ISNA(VLOOKUP(F25,tinh,2,FALSE)),"",VLOOKUP(F25,tinh,2,FALSE)) | I25: =IF(ISNA(VLOOKUP(H25&G25,huyen,3,FALSE)),"",VLOOKUP(H25&G25,huyen,3,FALSE)) | K25: =IF(ISNA(VLOOKUP(J25&I25,xa,3,FALSE)),"",VLOOKUP(J25&I25,xa,3,FALSE)) -> #REF! | N25: =IF(ISNA(VLOOKUP(M25,ma_mqh,2,FALSE)),"",VLOOKUP(M25,ma_mqh,2,FALSE)) | X25: =IF(ISNA(VLOOKUP(W25,tinh,2,FALSE)),"",VLOOKUP(W25,tinh,2,FALSE)) | Z25: =IF(ISNA(VLOOKUP(Y25&X25,huyen,3,FALSE)),"",VLOOKUP(Y25&X25,huyen,3,FALSE)) | AB25: =IF(ISNA(VLOOKUP(AA25&Z25,xa,3,FALSE)),"",VLOOKUP(AA25&Z25,xa,3,FALSE)) -> #REF! | AH25: =IF(ISNA(VLOOKUP(AG25,tinh,2,FALSE)),"",VLOOKUP(AG25,tinh,2,FALSE)) | AJ25: =IF(ISNA(VLOOKUP(AI25&AH25,huyen,3,FALSE)),"",VLOOKUP(AI25&AH25,huyen,3,FALSE)) | AL25: =IF(ISNA(VLOOKUP(AK25&AJ25,xa,3,FALSE)),"",VLOOKUP(AK25&AJ25,xa,3,FALSE)) -> #REF!
G26: =IF(ISNA(VLOOKUP(F26,tinh,2,FALSE)),"",VLOOKUP(F26,tinh,2,FALSE)) | I26: =IF(ISNA(VLOOKUP(H26&G26,huyen,3,FALSE)),"",VLOOKUP(H26&G26,huyen,3,FALSE)) | K26: =IF(ISNA(VLOOKUP(J26&I26,xa,3,FALSE)),"",VLOOKUP(J26&I26,xa,3,FALSE)) -> #REF! | N26: =IF(ISNA(VLOOKUP(M26,ma_mqh,2,FALSE)),"",VLOOKUP(M26,ma_mqh,2,FALSE)) | X26: =IF(ISNA(VLOOKUP(W26,tinh,2,FALSE)),"",VLOOKUP(W26,tinh,2,FALSE)) | Z26: =IF(ISNA(VLOOKUP(Y26&X26,huyen,3,FALSE)),"",VLOOKUP(Y26&X26,huyen,3,FALSE)) | AB26: =IF(ISNA(VLOOKUP(AA26&Z26,xa,3,FALSE)),"",VLOOKUP(AA26&Z26,xa,3,FALSE)) -> #REF! | AH26: =IF(ISNA(VLOOKUP(AG26,tinh,2,FALSE)),"",VLOOKUP(AG26,tinh,2,FALSE)) | AJ26: =IF(ISNA(VLOOKUP(AI26&AH26,huyen,3,FALSE)),"",VLOOKUP(AI26&AH26,huyen,3,FALSE)) | AL26: =IF(ISNA(VLOOKUP(AK26&AJ26,xa,3,FALSE)),"",VLOOKUP(AK26&AJ26,xa,3,FALSE)) -> #REF!
G27: =IF(ISNA(VLOOKUP(F27,tinh,2,FALSE)),"",VLOOKUP(F27,tinh,2,FALSE)) | I27: =IF(ISNA(VLOOKUP(H27&G27,huyen,3,FALSE)),"",VLOOKUP(H27&G27,huyen,3,FALSE)) | K27: =IF(ISNA(VLOOKUP(J27&I27,xa,3,FALSE)),"",VLOOKUP(J27&I27,xa,3,FALSE)) -> #REF! | N27: =IF(ISNA(VLOOKUP(M27,ma_mqh,2,FALSE)),"",VLOOKUP(M27,ma_mqh,2,FALSE)) | X27: =IF(ISNA(VLOOKUP(W27,tinh,2,FALSE)),"",VLOOKUP(W27,tinh,2,FALSE)) | Z27: =IF(ISNA(VLOOKUP(Y27&X27,huyen,3,FALSE)),"",VLOOKUP(Y27&X27,huyen,3,FALSE)) | AB27: =IF(ISNA(VLOOKUP(AA27&Z27,xa,3,FALSE)),"",VLOOKUP(AA27&Z27,xa,3,FALSE)) -> #REF! | AH27: =IF(ISNA(VLOOKUP(AG27,tinh,2,FALSE)),"",VLOOKUP(AG27,tinh,2,FALSE)) | AJ27: =IF(ISNA(VLOOKUP(AI27&AH27,huyen,3,FALSE)),"",VLOOKUP(AI27&AH27,huyen,3,FALSE)) | AL27: =IF(ISNA(VLOOKUP(AK27&AJ27,xa,3,FALSE)),"",VLOOKUP(AK27&AJ27,xa,3,FALSE)) -> #REF!
G28: =IF(ISNA(VLOOKUP(F28,tinh,2,FALSE)),"",VLOOKUP(F28,tinh,2,FALSE)) | I28: =IF(ISNA(VLOOKUP(H28&G28,huyen,3,FALSE)),"",VLOOKUP(H28&G28,huyen,3,FALSE)) | K28: =IF(ISNA(VLOOKUP(J28&I28,xa,3,FALSE)),"",VLOOKUP(J28&I28,xa,3,FALSE)) -> #REF! | N28: =IF(ISNA(VLOOKUP(M28,ma_mqh,2,FALSE)),"",VLOOKUP(M28,ma_mqh,2,FALSE)) | X28: =IF(ISNA(VLOOKUP(W28,tinh,2,FALSE)),"",VLOOKUP(W28,tinh,2,FALSE)) | Z28: =IF(ISNA(VLOOKUP(Y28&X28,huyen,3,FALSE)),"",VLOOKUP(Y28&X28,huyen,3,FALSE)) | AB28: =IF(ISNA(VLOOKUP(AA28&Z28,xa,3,FALSE)),"",VLOOKUP(AA28&Z28,xa,3,FALSE)) -> #REF! | AH28: =IF(ISNA(VLOOKUP(AG28,tinh,2,FALSE)),"",VLOOKUP(AG28,tinh,2,FALSE)) | AJ28: =IF(ISNA(VLOOKUP(AI28&AH28,huyen,3,FALSE)),"",VLOOKUP(AI28&AH28,huyen,3,FALSE)) | AL28: =IF(ISNA(VLOOKUP(AK28&AJ28,xa,3,FALSE)),"",VLOOKUP(AK28&AJ28,xa,3,FALSE)) -> #REF!
G29: =IF(ISNA(VLOOKUP(F29,tinh,2,FALSE)),"",VLOOKUP(F29,tinh,2,FALSE)) | I29: =IF(ISNA(VLOOKUP(H29&G29,huyen,3,FALSE)),"",VLOOKUP(H29&G29,huyen,3,FALSE)) | K29: =IF(ISNA(VLOOKUP(J29&I29,xa,3,FALSE)),"",VLOOKUP(J29&I29,xa,3,FALSE)) -> #REF! | N29: =IF(ISNA(VLOOKUP(M29,ma_mqh,2,FALSE)),"",VLOOKUP(M29,ma_mqh,2,FALSE)) | X29: =IF(ISNA(VLOOKUP(W29,tinh,2,FALSE)),"",VLOOKUP(W29,tinh,2,FALSE)) | Z29: =IF(ISNA(VLOOKUP(Y29&X29,huyen,3,FALSE)),"",VLOOKUP(Y29&X29,huyen,3,FALSE)) | AB29: =IF(ISNA(VLOOKUP(AA29&Z29,xa,3,FALSE)),"",VLOOKUP(AA29&Z29,xa,3,FALSE)) -> #REF! | AH29: =IF(ISNA(VLOOKUP(AG29,tinh,2,FALSE)),"",VLOOKUP(AG29,tinh,2,FALSE)) | AJ29: =IF(ISNA(VLOOKUP(AI29&AH29,huyen,3,FALSE)),"",VLOOKUP(AI29&AH29,huyen,3,FALSE)) | AL29: =IF(ISNA(VLOOKUP(AK29&AJ29,xa,3,FALSE)),"",VLOOKUP(AK29&AJ29,xa,3,FALSE)) -> #REF!
G30: =IF(ISNA(VLOOKUP(F30,tinh,2,FALSE)),"",VLOOKUP(F30,tinh,2,FALSE)) | I30: =IF(ISNA(VLOOKUP(H30&G30,huyen,3,FALSE)),"",VLOOKUP(H30&G30,huyen,3,FALSE)) | K30: =IF(ISNA(VLOOKUP(J30&I30,xa,3,FALSE)),"",VLOOKUP(J30&I30,xa,3,FALSE)) -> #REF! | N30: =IF(ISNA(VLOOKUP(M30,ma_mqh,2,FALSE)),"",VLOOKUP(M30,ma_mqh,2,FALSE)) | X30: =IF(ISNA(VLOOKUP(W30,tinh,2,FALSE)),"",VLOOKUP(W30,tinh,2,FALSE)) | Z30: =IF(ISNA(VLOOKUP(Y30&X30,huyen,3,FALSE)),"",VLOOKUP(Y30&X30,huyen,3,FALSE)) | AB30: =IF(ISNA(VLOOKUP(AA30&Z30,xa,3,FALSE)),"",VLOOKUP(AA30&Z30,xa,3,FALSE)) -> #REF! | AH30: =IF(ISNA(VLOOKUP(AG30,tinh,2,FALSE)),"",VLOOKUP(AG30,tinh,2,FALSE)) | AJ30: =IF(ISNA(VLOOKUP(AI30&AH30,huyen,3,FALSE)),"",VLOOKUP(AI30&AH30,huyen,3,FALSE)) | AL30: =IF(ISNA(VLOOKUP(AK30&AJ30,xa,3,FALSE)),"",VLOOKUP(AK30&AJ30,xa,3,FALSE)) -> #REF!
G31: =IF(ISNA(VLOOKUP(F31,tinh,2,FALSE)),"",VLOOKUP(F31,tinh,2,FALSE)) | I31: =IF(ISNA(VLOOKUP(H31&G31,huyen,3,FALSE)),"",VLOOKUP(H31&G31,huyen,3,FALSE)) | K31: =IF(ISNA(VLOOKUP(J31&I31,xa,3,FALSE)),"",VLOOKUP(J31&I31,xa,3,FALSE)) -> #REF! | N31: =IF(ISNA(VLOOKUP(M31,ma_mqh,2,FALSE)),"",VLOOKUP(M31,ma_mqh,2,FALSE)) | X31: =IF(ISNA(VLOOKUP(W31,tinh,2,FALSE)),"",VLOOKUP(W31,tinh,2,FALSE)) | Z31: =IF(ISNA(VLOOKUP(Y31&X31,huyen,3,FALSE)),"",VLOOKUP(Y31&X31,huyen,3,FALSE)) | AB31: =IF(ISNA(VLOOKUP(AA31&Z31,xa,3,FALSE)),"",VLOOKUP(AA31&Z31,xa,3,FALSE)) -> #REF! | AH31: =IF(ISNA(VLOOKUP(AG31,tinh,2,FALSE)),"",VLOOKUP(AG31,tinh,2,FALSE)) | AJ31: =IF(ISNA(VLOOKUP(AI31&AH31,huyen,3,FALSE)),"",VLOOKUP(AI31&AH31,huyen,3,FALSE)) | AL31: =IF(ISNA(VLOOKUP(AK31&AJ31,xa,3,FALSE)),"",VLOOKUP(AK31&AJ31,xa,3,FALSE)) -> #REF!
G32: =IF(ISNA(VLOOKUP(F32,tinh,2,FALSE)),"",VLOOKUP(F32,tinh,2,FALSE)) | I32: =IF(ISNA(VLOOKUP(H32&G32,huyen,3,FALSE)),"",VLOOKUP(H32&G32,huyen,3,FALSE)) | K32: =IF(ISNA(VLOOKUP(J32&I32,xa,3,FALSE)),"",VLOOKUP(J32&I32,xa,3,FALSE)) -> #REF! | N32: =IF(ISNA(VLOOKUP(M32,ma_mqh,2,FALSE)),"",VLOOKUP(M32,ma_mqh,2,FALSE)) | X32: =IF(ISNA(VLOOKUP(W32,tinh,2,FALSE)),"",VLOOKUP(W32,tinh,2,FALSE)) | Z32: =IF(ISNA(VLOOKUP(Y32&X32,huyen,3,FALSE)),"",VLOOKUP(Y32&X32,huyen,3,FALSE)) | AB32: =IF(ISNA(VLOOKUP(AA32&Z32,xa,3,FALSE)),"",VLOOKUP(AA32&Z32,xa,3,FALSE)) -> #REF! | AH32: =IF(ISNA(VLOOKUP(AG32,tinh,2,FALSE)),"",VLOOKUP(AG32,tinh,2,FALSE)) | AJ32: =IF(ISNA(VLOOKUP(AI32&AH32,huyen,3,FALSE)),"",VLOOKUP(AI32&AH32,huyen,3,FALSE)) | AL32: =IF(ISNA(VLOOKUP(AK32&AJ32,xa,3,FALSE)),"",VLOOKUP(AK32&AJ32,xa,3,FALSE)) -> #REF!
G33: =IF(ISNA(VLOOKUP(F33,tinh,2,FALSE)),"",VLOOKUP(F33,tinh,2,FALSE)) | I33: =IF(ISNA(VLOOKUP(H33&G33,huyen,3,FALSE)),"",VLOOKUP(H33&G33,huyen,3,FALSE)) | K33: =IF(ISNA(VLOOKUP(J33&I33,xa,3,FALSE)),"",VLOOKUP(J33&I33,xa,3,FALSE)) -> #REF! | N33: =IF(ISNA(VLOOKUP(M33,ma_mqh,2,FALSE)),"",VLOOKUP(M33,ma_mqh,2,FALSE)) | X33: =IF(ISNA(VLOOKUP(W33,tinh,2,FALSE)),"",VLOOKUP(W33,tinh,2,FALSE)) | Z33: =IF(ISNA(VLOOKUP(Y33&X33,huyen,3,FALSE)),"",VLOOKUP(Y33&X33,huyen,3,FALSE)) | AB33: =IF(ISNA(VLOOKUP(AA33&Z33,xa,3,FALSE)),"",VLOOKUP(AA33&Z33,xa,3,FALSE)) -> #REF! | AH33: =IF(ISNA(VLOOKUP(AG33,tinh,2,FALSE)),"",VLOOKUP(AG33,tinh,2,FALSE)) | AJ33: =IF(ISNA(VLOOKUP(AI33&AH33,huyen,3,FALSE)),"",VLOOKUP(AI33&AH33,huyen,3,FALSE)) | AL33: =IF(ISNA(VLOOKUP(AK33&AJ33,xa,3,FALSE)),"",VLOOKUP(AK33&AJ33,xa,3,FALSE)) -> #REF!
G34: =IF(ISNA(VLOOKUP(F34,tinh,2,FALSE)),"",VLOOKUP(F34,tinh,2,FALSE)) | I34: =IF(ISNA(VLOOKUP(H34&G34,huyen,3,FALSE)),"",VLOOKUP(H34&G34,huyen,3,FALSE)) | K34: =IF(ISNA(VLOOKUP(J34&I34,xa,3,FALSE)),"",VLOOKUP(J34&I34,xa,3,FALSE)) -> #REF! | N34: =IF(ISNA(VLOOKUP(M34,ma_mqh,2,FALSE)),"",VLOOKUP(M34,ma_mqh,2,FALSE)) | X34: =IF(ISNA(VLOOKUP(W34,tinh,2,FALSE)),"",VLOOKUP(W34,tinh,2,FALSE)) | Z34: =IF(ISNA(VLOOKUP(Y34&X34,huyen,3,FALSE)),"",VLOOKUP(Y34&X34,huyen,3,FALSE)) | AB34: =IF(ISNA(VLOOKUP(AA34&Z34,xa,3,FALSE)),"",VLOOKUP(AA34&Z34,xa,3,FALSE)) -> #REF! | AH34: =IF(ISNA(VLOOKUP(AG34,tinh,2,FALSE)),"",VLOOKUP(AG34,tinh,2,FALSE)) | AJ34: =IF(ISNA(VLOOKUP(AI34&AH34,huyen,3,FALSE)),"",VLOOKUP(AI34&AH34,huyen,3,FALSE)) | AL34: =IF(ISNA(VLOOKUP(AK34&AJ34,xa,3,FALSE)),"",VLOOKUP(AK34&AJ34,xa,3,FALSE)) -> #REF!
... G99: =IF(ISNA(VLOOKUP(F99,tinh,2,FALSE)),"",VLOOKUP(F99,tinh,2,FALSE)) | I99: =IF(ISNA(VLOOKUP(H99&G99,huyen,3,FALSE)),"",VLOOKUP(H99&G99,huyen,3,FALSE)) | K99: =IF(ISNA(VLOOKUP(J99&I99,xa,3,FALSE)),"",VLOOKUP(J99&I99,xa,3,FALSE)) -> #REF! | N99: =IF(ISNA(VLOOKUP(M99,ma_mqh,2,FALSE)),"",VLOOKUP(M99,ma_mqh,2,FALSE)) | X99: =IF(ISNA(VLOOKUP(W99,tinh,2,FALSE)),"",VLOOKUP(W99,tinh,2,FALSE)) | Z99: =IF(ISNA(VLOOKUP(Y99&X99,huyen,3,FALSE)),"",VLOOKUP(Y99&X99,huyen,3,FALSE)) | AB99: =IF(ISNA(VLOOKUP(AA99&Z99,xa,3,FALSE)),"",VLOOKUP(AA99&Z99,xa,3,FALSE)) -> #REF! | AH99: =IF(ISNA(VLOOKUP(AG99,tinh,2,FALSE)),"",VLOOKUP(AG99,tinh,2,FALSE)) | AJ99: =IF(ISNA(VLOOKUP(AI99&AH99,huyen,3,FALSE)),"",VLOOKUP(AI99&AH99,huyen,3,FALSE)) | AL99: =IF(ISNA(VLOOKUP(AK99&AJ99,xa,3,FALSE)),"",VLOOKUP(AK99&AJ99,xa,3,FALSE)) -> #REF!
G100: =IF(ISNA(VLOOKUP(F100,tinh,2,FALSE)),"",VLOOKUP(F100,tinh,2,FALSE)) | I100: =IF(ISNA(VLOOKUP(H100&G100,huyen,3,FALSE)),"",VLOOKUP(H100&G100,huyen,3,FALSE)) | K100: =IF(ISNA(VLOOKUP(J100&I100,xa,3,FALSE)),"",VLOOKUP(J100&I100,xa,3,FALSE)) -> #REF! | X100: =IF(ISNA(VLOOKUP(W100,tinh,2,FALSE)),"",VLOOKUP(W100,tinh,2,FALSE)) | Z100: =IF(ISNA(VLOOKUP(Y100&X100,huyen,3,FALSE)),"",VLOOKUP(Y100&X100,huyen,3,FALSE)) | AB100: =IF(ISNA(VLOOKUP(AA100&Z100,xa,3,FALSE)),"",VLOOKUP(AA100&Z100,xa,3,FALSE)) -> #REF! | AH100: =IF(ISNA(VLOOKUP(AG100,tinh,2,FALSE)),"",VLOOKUP(AG100,tinh,2,FALSE)) | AJ100: =IF(ISNA(VLOOKUP(AI100&AH100,huyen,3,FALSE)),"",VLOOKUP(AI100&AH100,huyen,3,FALSE)) | AL100: =IF(ISNA(VLOOKUP(AK100&AJ100,xa,3,FALSE)),"",VLOOKUP(AK100&AJ100,xa,3,FALSE)) -> #REF!
G101: =IF(ISNA(VLOOKUP(F101,tinh,2,FALSE)),"",VLOOKUP(F101,tinh,2,FALSE)) | I101: =IF(ISNA(VLOOKUP(H101&G101,huyen,3,FALSE)),"",VLOOKUP(H101&G101,huyen,3,FALSE)) | K101: =IF(ISNA(VLOOKUP(J101&I101,xa,3,FALSE)),"",VLOOKUP(J101&I101,xa,3,FALSE)) -> #REF! | X101: =IF(ISNA(VLOOKUP(W101,tinh,2,FALSE)),"",VLOOKUP(W101,tinh,2,FALSE)) | Z101: =IF(ISNA(VLOOKUP(Y101&X101,huyen,3,FALSE)),"",VLOOKUP(Y101&X101,huyen,3,FALSE)) | AB101: =IF(ISNA(VLOOKUP(AA101&Z101,xa,3,FALSE)),"",VLOOKUP(AA101&Z101,xa,3,FALSE)) -> #REF! | AH101: =IF(ISNA(VLOOKUP(AG101,tinh,2,FALSE)),"",VLOOKUP(AG101,tinh,2,FALSE)) | AJ101: =IF(ISNA(VLOOKUP(AI101&AH101,huyen,3,FALSE)),"",VLOOKUP(AI101&AH101,huyen,3,FALSE)) | AL101: =IF(ISNA(VLOOKUP(AK101&AJ101,xa,3,FALSE)),"",VLOOKUP(AK101&AJ101,xa,3,FALSE)) -> #REF!
G102: =IF(ISNA(VLOOKUP(F102,tinh,2,FALSE)),"",VLOOKUP(F102,tinh,2,FALSE)) | I102: =IF(ISNA(VLOOKUP(H102&G102,huyen,3,FALSE)),"",VLOOKUP(H102&G102,huyen,3,FALSE)) | K102: =IF(ISNA(VLOOKUP(J102&I102,xa,3,FALSE)),"",VLOOKUP(J102&I102,xa,3,FALSE)) -> #REF! | X102: =IF(ISNA(VLOOKUP(W102,tinh,2,FALSE)),"",VLOOKUP(W102,tinh,2,FALSE)) | Z102: =IF(ISNA(VLOOKUP(Y102&X102,huyen,3,FALSE)),"",VLOOKUP(Y102&X102,huyen,3,FALSE)) | AB102: =IF(ISNA(VLOOKUP(AA102&Z102,xa,3,FALSE)),"",VLOOKUP(AA102&Z102,xa,3,FALSE)) -> #REF! | AH102: =IF(ISNA(VLOOKUP(AG102,tinh,2,FALSE)),"",VLOOKUP(AG102,tinh,2,FALSE)) | AJ102: =IF(ISNA(VLOOKUP(AI102&AH102,huyen,3,FALSE)),"",VLOOKUP(AI102&AH102,huyen,3,FALSE)) | AL102: =IF(ISNA(VLOOKUP(AK102&AJ102,xa,3,FALSE)),"",VLOOKUP(AK102&AJ102,xa,3,FALSE)) -> #REF!
G103: =IF(ISNA(VLOOKUP(F103,tinh,2,FALSE)),"",VLOOKUP(F103,tinh,2,FALSE)) | I103: =IF(ISNA(VLOOKUP(H103&G103,huyen,3,FALSE)),"",VLOOKUP(H103&G103,huyen,3,FALSE)) | K103: =IF(ISNA(VLOOKUP(J103&I103,xa,3,FALSE)),"",VLOOKUP(J103&I103,xa,3,FALSE)) -> #REF! | X103: =IF(ISNA(VLOOKUP(W103,tinh,2,FALSE)),"",VLOOKUP(W103,tinh,2,FALSE)) | Z103: =IF(ISNA(VLOOKUP(Y103&X103,huyen,3,FALSE)),"",VLOOKUP(Y103&X103,huyen,3,FALSE)) | AB103: =IF(ISNA(VLOOKUP(AA103&Z103,xa,3,FALSE)),"",VLOOKUP(AA103&Z103,xa,3,FALSE)) -> #REF! | AH103: =IF(ISNA(VLOOKUP(AG103,tinh,2,FALSE)),"",VLOOKUP(AG103,tinh,2,FALSE)) | AJ103: =IF(ISNA(VLOOKUP(AI103&AH103,huyen,3,FALSE)),"",VLOOKUP(AI103&AH103,huyen,3,FALSE)) | AL103: =IF(ISNA(VLOOKUP(AK103&AJ103,xa,3,FALSE)),"",VLOOKUP(AK103&AJ103,xa,3,FALSE)) -> #REF!
G104: =IF(ISNA(VLOOKUP(F104,tinh,2,FALSE)),"",VLOOKUP(F104,tinh,2,FALSE)) | I104: =IF(ISNA(VLOOKUP(H104&G104,huyen,3,FALSE)),"",VLOOKUP(H104&G104,huyen,3,FALSE)) | K104: =IF(ISNA(VLOOKUP(J104&I104,xa,3,FALSE)),"",VLOOKUP(J104&I104,xa,3,FALSE)) -> #REF! | X104: =IF(ISNA(VLOOKUP(W104,tinh,2,FALSE)),"",VLOOKUP(W104,tinh,2,FALSE)) | Z104: =IF(ISNA(VLOOKUP(Y104&X104,huyen,3,FALSE)),"",VLOOKUP(Y104&X104,huyen,3,FALSE)) | AB104: =IF(ISNA(VLOOKUP(AA104&Z104,xa,3,FALSE)),"",VLOOKUP(AA104&Z104,xa,3,FALSE)) -> #REF! | AH104: =IF(ISNA(VLOOKUP(AG104,tinh,2,FALSE)),"",VLOOKUP(AG104,tinh,2,FALSE)) | AJ104: =IF(ISNA(VLOOKUP(AI104&AH104,huyen,3,FALSE)),"",VLOOKUP(AI104&AH104,huyen,3,FALSE)) | AL104: =IF(ISNA(VLOOKUP(AK104&AJ104,xa,3,FALSE)),"",VLOOKUP(AK104&AJ104,xa,3,FALSE)) -> #REF!
