Workbook
Name RangeData36: '[1]Dữ liệu nhập liệu'!$AK$3:$AK$241
Name RangeData46: '[2]Dữ liệu nhập liệu'!$AU$3:$AU$11181
Name RangeData69: '[1]Dữ liệu nhập liệu'!$BR$3:$BR$4

Sheet TT
B1: THÔNG TIN THỜI VỤ 2024
B2: 1 | C2: 2 | D2: 3 | E2: 4 | F2: 5 | G2: 6 | H2: 7 | I2: 8 | J2: 9 | K2: 10 | L2: 11 | M2: 12 | N2: 13 | O2: 14 | P2: 15 | Q2: 16
A3: STT | B3: Mã NV | C3: HỌ VÀ TÊN | D3: NGÀY SINH | E3: BP | F3: SỐ CMT | G3: NGÀY CẤP | H3: NƠI CẤP | I3: ĐỊA CHỈ | J3: SỐ ĐT | K3: Giới tính | L3: Ngày vào | M3: Ca | N3: VT | O3: Vendor | P3: Đến ngày | Q3: Trạng thái | R3: Phân loại | S3: Kinh nghiệm làm việc | U3: Vị trí làm việc | Y3: Ghi chú
S4: Công ty | T4: Thời gian | U4: Ngoại quan | V4: Chức năng | W4: Lắp ráp | X4: Bắt vít
A5: 1 | B5: NW24011669HM | C5: Nguyễn Văn Tính | D5: 38091 | E5: P | F5: 019204011597 | G5: 44793 | H5: Cục Cảnh sát | I5: Nga My - Phú Bình - Thái Nguyê | J5: 0379127290 | K5: Nam | L5: 45293 | M5: Ngày | N5: 272 | O5: =RIGHT(B5,2) -> HM | P5: =VLOOKUP($B5,'[3]CHÍNH THỨC'!$D:$H,4,0) -> 45317 | Q5: =VLOOKUP($B5,'[3]CHÍNH THỨC'!$D:$H,5,0) -> Đã nghỉ việc
A6: 2 | B6: 24011670HM | C6: Hoàng Thị Dần | D6: 29085 | E6: P | F6: 019179001028 | G6: 44299 | H6: Cục Cảnh sát | I6: Tức Tranh - Phú Lương - Thái Nguyên | J6: 0384334882 | K6: Nữ | L6: 45293 | M6: Ngày | N6: 273 | O6: =RIGHT(B6,2) -> HM | P6: =VLOOKUP($B6,'[3]CHÍNH THỨC'!$D:$H,4,0) -> 45925 | Q6: =VLOOKUP($B6,'[3]CHÍNH THỨC'!$D:$H,5,0) -> Đang làm việc
A7: 3 | B7: NW24011671HM | C7: Phạm Thị Hồng Liên | D7: 38244 | E7: P | F7: 019304009288 | G7: 44329 | H7: Cục Cảnh sát | I7: Khôi Kỳ - Đại Từ - Thái Nguyên | J7: 0876275617 | K7: Nữ | L7: 45293 | M7: Ngày | N7: 274 | O7: =RIGHT(B7,2) -> HM | P7: =VLOOKUP($B7,'[3]CHÍNH THỨC'!$D:$H,4,0) -> 45294 | Q7: =VLOOKUP($B7,'[3]CHÍNH THỨC'!$D:$H,5,0) -> Đã nghỉ việc
A8: 4 | B8: NW24011672HM | C8: Nguyễn Hồng Nhung | D8: 38452 | E8: P | F8: 019305006961 | G8: 44424 | H8: Cục Cảnh sát | I8: Túc Duyên - TP Thái Nguyên - Thái Nguyên | J8: 0337989023 | K8: Nữ | L8: 45293 | M8: Ngày | N8: 277 | O8: =RIGHT(B8,2) -> HM | P8: =VLOOKUP($B8,'[3]CHÍNH THỨC'!$D:$H,4,0) -> 45328 | Q8: =VLOOKUP($B8,'[3]CHÍNH THỨC'!$D:$H,5,0) -> Đã nghỉ việc
A9: 5 | B9: NW24011673HM | C9: Dương Văn Quyết | D9: 38445 | E9: P | F9: 002205005603 | G9: 37614 | H9: Cục Cảnh sát | I9: Yên Đổ - Phú Lương - Thái Nguyên | J9: 0329965017 | K9: Nam | L9: 45293 | M9: Ngày | N9: 281 | O9: =RIGHT(B9,2) -> HM | P9: =VLOOKUP($B9,'[3]CHÍNH THỨC'!$D:$H,4,0) -> 45321 | Q9: =VLOOKUP($B9,'[3]CHÍNH THỨC'!$D:$H,5,0) -> Đã nghỉ việc
A10: 6 | B10: NW24011674HM | C10: Đặng Hoàng Vũ | D10: 38617 | E10: P | F10: 014205007491 | G10: 37614 | H10: Cục Cảnh sát | I10: Quân Chu - Đại Từ - Thái Nguyên | J10: 0348114708 | K10: Nam | L10: 45293 | M10: Ngày | N10: 288 | O10: =RIGHT(B10,2) -> HM | P10: =VLOOKUP($B10,'[3]CHÍNH THỨC'!$D:$H,4,0) -> 45310 | Q10: =VLOOKUP($B10,'[3]CHÍNH THỨC'!$D:$H,5,0) -> Đã nghỉ việc
A11: 7 | B11: NW24010180MA | C11: Hà Xuân Doãn | D11: 38382 | E11: P | F11: 006205003239 | G11: 44325 | H11: Cục Cảnh Sát | I11: Cao Kỳ - Chợ Mới - Bắc Kạn | J11: 0344978262 | K11: Nam | L11: 45293 | M11: Ngày | N11: 241 | O11: =RIGHT(B11,2) -> MA | P11: =VLOOKUP($B11,'[3]CHÍNH THỨC'!$D:$H,4,0) -> 45294 | Q11: =VLOOKUP($B11,'[3]CHÍNH THỨC'!$D:$H,5,0) -> Đã nghỉ việc
A12: 8 | B12: NW24010181MA | C12: Nguyễn Văn Dũng | D12: 37702 | E12: P | F12: 012203006498 | G12: 44534 | H12: Cục Cảnh Sát | I12: Hồ Mít - Tân Uyên - Lai Châu | J12: 0362642737 | K12: Nam | L12: 45293 | M12: Đêm | N12: 245 | O12: =RIGHT(B12,2) -> MA | P12: =VLOOKUP($B12,'[3]CHÍNH THỨC'!$D:$H,4,0) -> 45329 | Q12: =VLOOKUP($B12,'[3]CHÍNH THỨC'!$D:$H,5,0) -> Đã nghỉ việc
A13: 9 | B13: NW24010182MA | C13: Dương Thế Hoàn | D13: 37209 | E13: P | F13: 019201006468 | G13: 45060 | H13: Cục Cảnh Sát | I13: Xuân Phương - Phú Bình - Thái Nguyên | J13: 0986044475 | K13: Nam | L13: 45293 | M13: Ngày | N13: 249 | O13: =RIGHT(B13,2) -> MA | P13: =VLOOKUP($B13,'[3]CHÍNH THỨC'!$D:$H,4,0) -> 45317 | Q13: =VLOOKUP($B13,'[3]CHÍNH THỨC'!$D:$H,5,0) -> Đã nghỉ việc
A14: 10 | B14: NW24010183MA | C14: Lý Viêt Đức | D14: 38650 | E14: P | F14: 019205010095 | G14: 44547 | H14: Cục Cảnh Sát | I14: Phú Đình - Định Hóa - Thái Nguyên | J14: 0974893344 | K14: Nam | L14: 45293 | M14: Ngày | N14: 250 | O14: =RIGHT(B14,2) -> MA | P14: =VLOOKUP($B14,'[3]CHÍNH THỨC'!$D:$H,4,0) -> 45303 | Q14: =VLOOKUP($B14,'[3]CHÍNH THỨC'!$D:$H,5,0) -> Đã nghỉ việc
A15: 11 | B15: NW24010184MA | C15: Trần Anh Thắng | D15: 37857 | E15: P | F15: 025203012812 | G15: 44382 | H15: Cục Cảnh Sát | I15: Tinh Nhuệ - Thanh Sơn - Phú Thọ | J15: 0974893344 | K15: Nam | L15: 45293 | M15: Ngày | N15: 252 | O15: =RIGHT(B15,2) -> MA | P15: =VLOOKUP($B15,'[3]CHÍNH THỨC'!$D:$H,4,0) -> 45303 | Q15: =VLOOKUP($B15,'[3]CHÍNH THỨC'!$D:$H,5,0) -> Đã nghỉ việc
A16: 12 | B16: NW24010185MA | C16: Nguyễn Văn Tuấn | D16: 38509 | E16: P | F16: 019205009222 | G16: 44347 | H16: Cục Cảnh Sát | I16: Văn Yên - Đại Từ - Thái Nguyên | J16: 0385746255 | K16: Nam | L16: 45293 | M16: Ngày | N16: 256 | O16: =RIGHT(B16,2) -> MA | P16: =VLOOKUP($B16,'[3]CHÍNH THỨC'!$D:$H,4,0) -> 45301 | Q16: =VLOOKUP($B16,'[3]CHÍNH THỨC'!$D:$H,5,0) -> Đã nghỉ việc
A17: 13 | B17: NW24010186MA | C17: Đinh Thị Điệp Anh | D17: 38680 | E17: P | F17: 006305000533 | G17: 44310 | H17: Cục Cảnh Sát | I17: Vũ Muộn - Bình Thuận - Bắc Kạn | J17: 0336482442 | K17: Nữ | L17: 45293 | M17: Đêm | N17: 263 | O17: =RIGHT(B17,2) -> MA | P17: =VLOOKUP($B17,'[3]CHÍNH THỨC'!$D:$H,4,0) -> 45329 | Q17: =VLOOKUP($B17,'[3]CHÍNH THỨC'!$D:$H,5,0) -> Đã nghỉ việc
A18: 14 | B18: NW24010187MA | C18: Đinh Quỳnh Nga | D18: 38667 | E18: P | F18: 006305000599 | G18: 44327 | H18: Cục Cảnh Sát | I18: Vũ Muộn - Bình Thuận - Bắc Kạn | J18: 0336482442 | K18: Nữ | L18: 45293 | M18: Đêm | N18: 266 | O18: =RIGHT(B18,2) -> MA | P18: =VLOOKUP($B18,'[3]CHÍNH THỨC'!$D:$H,4,0) -> 45329 | Q18: =VLOOKUP($B18,'[3]CHÍNH THỨC'!$D:$H,5,0) -> Đã nghỉ việc
A19: 15 | B19: NW24011581HL | C19: Võ Thùy Linh | D19: 38307 | E19: P | F19: 019304009349 | G19: 44374 | H19: Cục Cảnh Sát | I19: Tân Kim - Phú Bình -Thái Nguyên | J19: 0979138305 | K19: Nữ | L19: 45293 | M19: Ngày | N19: 293 | O19: =RIGHT(B19,2) -> HL | P19: =VLOOKUP($B19,'[3]CHÍNH THỨC'!$D:$H,4,0) -> 45317 | Q19: =VLOOKUP($B19,'[3]CHÍNH THỨC'!$D:$H,5,0) -> Đã nghỉ việc
A20: 16 | B20: NW24011582HL | C20: Lục Văn Thành | D20: 34429 | E20: P | F20: 019094000911 | G20: 44311 | H20: Cục Cảnh Sát | I20: Tân Long - Đồng Hỷ - Thái Nguyên | J20: 0865929478 | K20: Nam | L20: 45293 | M20: Đêm | N20: 294 | O20: =RIGHT(B20,2) -> HL | P20: =VLOOKUP($B20,'[3]CHÍNH THỨC'!$D:$H,4,0) -> 45329 | Q20: =VLOOKUP($B20,'[3]CHÍNH THỨC'!$D:$H,5,0) -> Đã nghỉ việc
A21: 17 | B21: NW24011583HL | C21: Nguyễn Thị Mỹ Linh | D21: 38471 | E21: P | F21: 019305002205 | G21: 44425 | H21: Cục Cảnh Sát | I21: Tiên Phong - Phổ Yên - Thái Nguyên | J21: 0867648546 | K21: Nữ | L21: 45293 | M21: Ngày | N21: 297 | O21: =RIGHT(B21,2) -> HL | P21: =VLOOKUP($B21,'[3]CHÍNH THỨC'!$D:$H,4,0) -> 45306 | Q21: =VLOOKUP($B21,'[3]CHÍNH THỨC'!$D:$H,5,0) -> Đã nghỉ việc
A22: 18 | B22: NW24011584HL | C22: Trạc Thị Thu Hằng | D22: 36993 | E22: P | F22: 019301008204 | G22: 44389 | H22: Cục Cảnh Sát | I22: Tức Tranh - Phú Lương - Thái Nguyên | J22: 0372164146 | K22: Nữ | L22: 45293 | M22: Ngày | N22: 306 | O22: =RIGHT(B22,2) -> HL | P22: =VLOOKUP($B22,'[3]CHÍNH THỨC'!$D:$H,4,0) -> 45313 | Q22: =VLOOKUP($B22,'[3]CHÍNH THỨC'!$D:$H,5,0) -> Đã nghỉ việc
A23: 19 | B23: NW24011585HL | C23: Lê Thị Hậu | D23: 37038 | E23: P | F23: 019301006334 | G23: 44440 | H23: Cục Cảnh Sát | I23: Tân Đức - Phú Bình - Thái Nguyên | J23: 0965307691 | K23: Nữ | L23: 45293 | M23: Ngày | N23: 309 | O23: =RIGHT(B23,2) -> HL | P23: =VLOOKUP($B23,'[3]CHÍNH THỨC'!$D:$H,4,0) -> 45313 | Q23: =VLOOKUP($B23,'[3]CHÍNH THỨC'!$D:$H,5,0) -> Đã nghỉ việc
A24: 20 | B24: NW24011586HL | C24: Dương Quang Hưng | D24: 35197 | E24: P | F24: 019096006721 | G24: 44939 | H24: Cục Cảnh Sát | I24: Xuân Phương - Phú Bình - Thái Nguyên | J24: 0867947221 | K24: Nam | L24: 45293 | M24: Ngày | N24: 317 | O24: =RIGHT(B24,2) -> HL | P24: =VLOOKUP($B24,'[3]CHÍNH THỨC'!$D:$H,4,0) -> 45328 | Q24: =VLOOKUP($B24,'[3]CHÍNH THỨC'!$D:$H,5,0) -> Đã nghỉ việc
A25: 21 | B25: NW24011587HL | C25: Ngô Thị Tình | D25: 37782 | E25: P | F25: 019303008418 | G25: 45073 | H25: Cục Cảnh Sát | I25: Minh Đức - Phổ Yên - Thái Nguyên | J25: 0362702953 | K25: Nữ | L25: 45293 | M25: Đêm | N25: 321 | O25: =RIGHT(B25,2) -> HL | P25: =VLOOKUP($B25,'[3]CHÍNH THỨC'!$D:$H,4,0) -> 45300 | Q25: =VLOOKUP($B25,'[3]CHÍNH THỨC'!$D:$H,5,0) -> Đã nghỉ việc
... A33: 29 | B33: NW24010068MD | C33: Nguyễn Thị Lan Anh | D33: 29709 | E33: P | F33: 019181013474 | G33: 44469 | H33: Cục Cảnh Sát | I33: Tân Hương, Phổ Yên, Thái Nguyên | J33: 0972382674 | K33: Nữ | L33: 45293 | M33: Đêm | N33: 342 | O33: =RIGHT(B33,2) -> MD | P33: =VLOOKUP($B33,'[3]CHÍNH THỨC'!$D:$H,4,0) -> 45352 | Q33: =VLOOKUP($B33,'[3]CHÍNH THỨC'!$D:$H,5,0) -> Đã nghỉ việc
A34: 30 | B34: NW24010069MD | C34: Hoàng Thị Thủy | D34: 30156 | E34: P | F34: 019182008241 | G34: 44419 | H34: Cục Cảnh Sát | I34: Hòa Bình, Đồng Hỷ, Thái Nguyên | J34: 0911239743 | K34: Nữ | L34: 45293 | M34: Đêm | N34: 356 | O34: =RIGHT(B34,2) -> MD | P34: =VLOOKUP($B34,'[3]CHÍNH THỨC'!$D:$H,4,0) -> 45329 | Q34: =VLOOKUP($B34,'[3]CHÍNH THỨC'!$D:$H,5,0) -> Đã nghỉ việc
A35: 31 | B35: NW24010070MD | C35: Trần Thị Hằng | D35: 29022 | E35: P | F35: 019179004731 | G35: 44419 | H35: Cục Cảnh Sát | I35: Hóa Trung, Đồng Hỷ, Thái Nguyên | J35: 0374863135 | K35: Nữ | L35: 45293 | M35: Đêm | N35: 357 | O35: =RIGHT(B35,2) -> MD | P35: =VLOOKUP($B35,'[3]CHÍNH THỨC'!$D:$H,4,0) -> 45329 | Q35: =VLOOKUP($B35,'[3]CHÍNH THỨC'!$D:$H,5,0) -> Đã nghỉ việc
A36: 32 | B36: NW24011049TM | C36: Nguyễn Văn Toàn | D36: 30597 | E36: P | F36: 019083013176 | G36: 44205 | H36: Cục Cảnh Sát | I36: Xóm Đô - Nhã Lộng - Phú Bình - Thái Nguyên | J36: 0356354977 | K36: Nam | L36: 45293 | M36: Ngày | N36: 271 | O36: =RIGHT(B36,2) -> TM | P36: =VLOOKUP($B36,'[3]CHÍNH THỨC'!$D:$H,4,0) -> 45313 | Q36: =VLOOKUP($B36,'[3]CHÍNH THỨC'!$D:$H,5,0) -> Đã nghỉ việc
A37: 33 | B37: NW24010028MU | C37: Hứa Văn Vương | D37: 33784 | E37: P | F37: 004092007605 | G37: 44894 | H37: Cục Cảnh Sát | I37: Cẩn Yên, Hà Quảng, Cao Bằng | J37: 0382608126 | K37: Nam | L37: 45293 | M37: Ngày | N37: 231 | O37: =RIGHT(B37,2) -> MU | P37: =VLOOKUP($B37,'[3]CHÍNH THỨC'!$D:$H,4,0) -> 45336 | Q37: =VLOOKUP($B37,'[3]CHÍNH THỨC'!$D:$H,5,0) -> Đã nghỉ việc
A38: 34 | B38: NW24010221LT | C38: Nguyễn Thị Hằng | D38: 38403 | E38: P | F38: 019305002782 | G38: 44313 | H38: Cục Cảnh Sát | I38: Quang Vinh - T.P Thái Nguyên - Thái Nguyên | J38: 0369950545 | K38: Nữ | L38: 45293 | M38: Ngày | N38: 236 | O38: =RIGHT(B38,2) -> LT | P38: =VLOOKUP($B38,'[3]CHÍNH THỨC'!$D:$H,4,0) -> 45303 | Q38: =VLOOKUP($B38,'[3]CHÍNH THỨC'!$D:$H,5,0) -> Đã nghỉ việc
A39: 35 | B39: NW24010222LT | C39: Nguyễn Văn Đông | D39: 37820 | E39: P | F39: 019203011482 | G39: 44381 | H39: Cục Cảnh Sát | I39: Động Đạt - Phú Lương - Thái Nguyên | J39: 0396114892 | K39: Nam | L39: 45293 | M39: Ngày | N39: 235 | O39: =RIGHT(B39,2) -> LT | P39: =VLOOKUP($B39,'[3]CHÍNH THỨC'!$D:$H,4,0) -> 45302 | Q39: =VLOOKUP($B39,'[3]CHÍNH THỨC'!$D:$H,5,0) -> Đã nghỉ việc
A40: 36 | B40: NW24010223LT | C40: Nguyễn Minh Hoàng | D40: 35695 | E40: P | F40: 019097008783 | G40: 44894 | H40: Cục Cảnh Sát | I40: Lương Sơn - T.P Sông Công- Thái Nguyên | J40: 0395081196 | K40: Nam | L40: 45293 | M40: Ngày | N40: 232 | O40: =RIGHT(B40,2) -> LT | P40: =VLOOKUP($B40,'[3]CHÍNH THỨC'!$D:$H,4,0) -> 45323 | Q40: =VLOOKUP($B40,'[3]CHÍNH THỨC'!$D:$H,5,0) -> Đã nghỉ việc
A41: 37 | B41: NW24010224LT | C41: Trần Anh Thái | D41: 34939 | E41: P | F41: 019095010114 | G41: 44467 | H41: Cục Cảnh Sát | I41: Tân Thành - T.P Thái Nguyên - Thái Nguyên | J41: 0799795666 | K41: Nam | L41: 45293 | M41: Đêm | N41: 343 | O41: =RIGHT(B41,2) -> LT | P41: =VLOOKUP($B41,'[3]CHÍNH THỨC'!$D:$H,4,0) -> 45295 | Q41: =VLOOKUP($B41,'[3]CHÍNH THỨC'!$D:$H,5,0) -> Đã nghỉ việc
A42: 38 | B42: NW24011675HM | C42: Lâm Tiến Định | D42: 38419 | E42: P | F42: 019205007151 | G42: 44329 | H42: Cục Cảnh sát | I42: Bắc Sơn - Phổ Yên - Thái Nguyên | J42: 0985157597 | K42: Nam | L42: 45294 | M42: Ngày | N42: 344 | O42: =RIGHT(B42,2) -> HM | P42: =VLOOKUP($B42,'[3]CHÍNH THỨC'!$D:$H,4,0) -> 45548 | Q42: =VLOOKUP($B42,'[3]CHÍNH THỨC'!$D:$H,5,0) -> Đã nghỉ việc
A43: 39 | B43: NW24011676HM | C43: Lâm Văn Thắng | D43: 38674 | E43: P | F43: 019207011303 | G43: 44280 | H43: Cục Cảnh sát | I43: Bắc Sơn - Phổ Yên - Thái Nguyên | J43: 0877797004 | K43: Nam | L43: 45294 | M43: Ngày | N43: 346 | O43: =RIGHT(B43,2) -> HM | P43: =VLOOKUP($B43,'[3]CHÍNH THỨC'!$D:$H,4,0) -> 45338 | Q43: =VLOOKUP($B43,'[3]CHÍNH THỨC'!$D:$H,5,0) -> Đã nghỉ việc
A44: 40 | B44: NW24011677HM | C44: Triệu Thị Truyền | D44: 34325 | E44: P | F44: 008193006708 | G44: 45035 | H44: Cục Cảnh sát | I44: Bạch Xa - Hàm Yên - Tuyên Quang | J44: 0964229891 | K44: Nữ | L44: 45294 | M44: Ngày | N44: 398 | O44: =RIGHT(B44,2) -> HM | P44: =VLOOKUP($B44,'[3]CHÍNH THỨC'!$D:$H,4,0) -> 45317 | Q44: =VLOOKUP($B44,'[3]CHÍNH THỨC'!$D:$H,5,0) -> Đã nghỉ việc
A45: 41 | B45: NW24011678HM | C45: Hoàng Trường Giang | D45: 35105 | E45: P | F45: 095210719 | G45: 42781 | H45: CA Bắc Kạn | I45: Huyền Tụng -TP Bắc Kạn - Bắc Kạn | J45: 0988615501 | K45: Nam | L45: 45294 | M45: Đêm | N45: 403 | O45: =RIGHT(B45,2) -> HM | P45: =VLOOKUP($B45,'[3]CHÍNH THỨC'!$D:$H,4,0) -> 45300 | Q45: =VLOOKUP($B45,'[3]CHÍNH THỨC'!$D:$H,5,0) -> Đã nghỉ việc
A46: 42 | B46: NW24011679HM | C46: Nguyễn Thị Lan Anh | D46: 38123 | E46: P | F46: 019304001830 | G46: 44579 | H46: Cục Cảnh sát | I46: Nhã Lộng - Phú Bình - Thái Nguyên | J46: 0766471686 | K46: Nữ | L46: 45294 | M46: Ngày | N46: 405 | O46: =RIGHT(B46,2) -> HM | P46: =VLOOKUP($B46,'[3]CHÍNH THỨC'!$D:$H,4,0) -> 45306 | Q46: =VLOOKUP($B46,'[3]CHÍNH THỨC'!$D:$H,5,0) -> Đã nghỉ việc
A47: 43 | B47: NW24011680HM | C47: Nguyễn Mạnh Hưng | D47: 37595 | E47: P | F47: 019202006425 | G47: 44994 | H47: Cục Cảnh sát | I47: Thuận Thành - Phổ Yên - Thái nguyên | J47: 0328974047 | K47: Nam | L47: 45294 | M47: Ngày | N47: 408 | O47: =RIGHT(B47,2) -> HM | P47: =VLOOKUP($B47,'[3]CHÍNH THỨC'!$D:$H,4,0) -> 45300 | Q47: =VLOOKUP($B47,'[3]CHÍNH THỨC'!$D:$H,5,0) -> Đã nghỉ việc
...

Sheet VT
B4: NW24011670HM | C4: =VLOOKUP($B4,TT!$B:$O,13,0) -> #N/A
B5: NW24011675HM | C5: =VLOOKUP($B5,TT!$B:$O,13,0) -> 344
B6: NW24021630HL | C6: =VLOOKUP($B6,TT!$B:$O,13,0) -> 230
B7: NW24021631HL | C7: =VLOOKUP($B7,TT!$B:$O,13,0) -> 231
B8: NW24030085MD | C8: =VLOOKUP($B8,TT!$B:$O,13,0) -> 281
B9: NW24030095MD | C9: =VLOOKUP($B9,TT!$B:$O,13,0) -> 520
B10: NW24031660HL | C10: =VLOOKUP($B10,TT!$B:$O,13,0) -> 594
B11: NW24030255LT | C11: =VLOOKUP($B11,TT!$B:$O,13,0) -> 236
B12: NW24030231MA | C12: =VLOOKUP($B12,TT!$B:$O,13,0) -> 745
B13: NW24031679HL | C13: =VLOOKUP($B13,TT!$B:$O,13,0) -> 746
B14: NW24031685HL | C14: =VLOOKUP($B14,TT!$B:$O,13,0) -> #N/A
B15: NW24031761HM | C15: =VLOOKUP($B15,TT!$B:$O,13,0) -> 629
... B602: NW24070234MD | C602: =VLOOKUP($B602,TT!$B:$O,13,0) -> 1377

Sheet Nghỉ việc
B2: No | C2: Mã NV | D2: Họ và Tên | E2: Bộ phận | F2: Ngày vào | G2: Ngày xử lý nghỉ việc | H2: Tổng thời gian làm việc | I2: Lý do nghỉ việc | J2: Số điện thoại
B3: 1 | C3: NW24092130HM | D3: Lưu Sỹ Bắc | E3: SM | F3: 45552 | G3: 45553 | H3: =G3-F3 -> 1 | I3: Nghỉ KLD 2 ngày. CN báo nghỉ luôn | J3: 0946290654
B4: 2 | C4: NW24070295CE | D4: Nguyễn Thị Hà | E4: Q | F4: 45482 | G4: 4-thg 9-24 | H4: 57 | I4: Nghỉ 2 ngày KLD, bỏ việc đã xác nhận | J4: 971747908
B5: 3 | C5: NW24050288MA | D5: Dương Thuỳ Linh | E5: Q | F5: 45427 | G5: 4-thg 9-24 | H5: 112 | I5: Bỏ việc đã xác nhận | J5: 393185944
B6: 4 | C6: NW24070224MD | D6: Trần Thị Kiều Linh | E6: Q | F6: 45483 | G6: 6-thg 9-24 | H6: 58 | I6: Bỏ việc đã xác nhận | J6: 357563608
B7: 5 | C7: NW24091676NE | D7: Trần Phương Đông | E7: Q | F7: 45391 | G7: 5-thg 9-24 | H7: 1 | I7: Nghỉ KLD 2 ngày đã xác nhận | J7: 334440127
B8: 6 | C8: NW24090402MA | D8: Đặng Kim Tuyến | E8: Q | F8: 45391 | G8: 7-thg 9-24 | H8: 3 | I8: Nghỉ KLD 2 ngày đã xác nhận | J8: 332964935
B9: 7 | C9: NW24090256MD | D9: Đặng Xuân Tiến | E9: Q | F9: 45391 | G9: 7-thg 9-24 | H9: 3 | I9: Bỏ việc đã xác nhận | J9: 369191040
B10: 8 | C10: NW24092106HM | D10: Nông Thị Nguyên | E10: Q | F10: 45544 | G10: 12-thg 9-24 | H10: 3 | I10: Bỏ việc đã xác nhận | J10: 345383205
B11: 9 | C11: NW24092120HM | D11: Hoàng Nữ Nhi | E11: Q | F11: 9/14/2024 | G11: 16-thg 9-24 | H11: 2 | I11: 2 ngày KLD đã xác nhận | J11: 386881147
B12: 10 | C12: NW24092121HM | D12: Nguyễn Việt Bắc | E12: Q | F12: 9/14/2024 | G12: 16-thg 9-24 | H12: 2 | I12: 2 ngày KLD đã xác nhận | J12: 393998606
B13: 11 | C13: NW24092107HM | D13: Lò Minh Thông | E13: Q | F13: 45544 | G13: 9/16/2024 | H13: 7 | I13: 2 ngày KLD đã xác nhận | J13: 986359370
B14: 12 | C14: NW24092118HM | D14: Nguyễn Văn Học | E14: Q | F14: 9/14/2024 | G14: 9/16/2024 | H14: 2 | I14: 2 ngày KLD đã xác nhận | J14: 979407568
B15: 13 | C15: NW24092119HM | D15: Nguyễn Văn Vũ | E15: Q | F15: 9/14/2024 | G15: 9/16/2024 | H15: 2 | I15: 2 ngày KLD đã xác nhận | J15: 373500609
B16: 14 | C16: NW24090283MD | D16: Hoàng Thị Hồng | E16: Q | F16: 9/16/2024 | G16: 9/17/2024 | H16: 1 | I16: 2 ngày KLD đã xác nhận | J16: 369734249
B17: 15 | C17: NW24091708NE | D17: Nguyễn Thị Tiếp | E17: Q | F17: 9/14/2024 | G17: 9/18/2024 | H17: 4 | I17: Bỏ việc đã xác nhận | J17: 986142768
B18: 16 | C18: NW24092129HM | D18: Lê Việt Dũng | E18: Q | F18: 9/16/2024 | G18: 9/18/2024 | H18: 2 | I18: Không tuân thủ quy định | J18: 866002660
B19: 17 | C19: NW24092127HM | D19: Lường Minh Nghĩa | E19: Q | F19: 9/16/2024 | G19: 9/17/2024 | H19: 1 | I19: 2 ngày KLD đã xác nhận | J19: 333903287
B20: 18 | C20: NW24092128HM | D20: Vi Văn Hội | E20: Q | F20: 9/16/2024 | G20: 9/17/2024 | H20: 1 | I20: 2 ngày KLD đã xác nhận | J20: 356711415
B21: 19 | C21: NW24090286MD | D21: Phạm Quốc Huy | E21: Q | F21: 9/17/2024 | G21: 9/18/2024 | H21: 1 | I21: 2 ngày KLD đã xác nhận | J21: 366263227
B22: 20 | C22: NW24090287MD | D22: Nguyễn Thị Thúy Anh | E22: Q | F22: 9/17/2024 | G22: 9/18/2024 | H22: 1 | I22: 2 ngày KLD đã xác nhận | J22: 353258931
B23: 21 | C23: NW24091716NE | D23: Dương Xuân Thu | E23: Q | F23: 9/19/2024 | G23: 9/20/2024 | H23: 1 | I23: Không tuân thủ quy định | J23: 342469135
B24: 22 | C24: NW24091717NE | D24: Trịnh Việt Anh | E24: Q | F24: 9/19/2024 | G24: 9/20/2024 | H24: 1 | I24: Không tuân thủ quy định | J24: 334440127
B25: 23 | C25: NW24092125HM | D25: Lý Thanh Tùng | E25: P | F25: 16.09.2024 | G25: 19.09.2024 | H25: 3 | I25: Nghỉ không lý do 2 ngày | J25: 356483294
... B27: 25 | C27: NW24091710NE | D27: Nguyễn Văn Thành | E27: P | F27: 17.09.2024 | G27: 19.09.2024 | H27: 2 | I27: Không tuân thủ quy định | J27: 334440127
B28: 26 | C28: NW24091684NE | D28: Long Thanh Mười | E28: PW | F28: 10.09.2024 | G28: 19.09.2024 | H28: 10 | I28: Công nhân xin nghỉ việc
B29: 27 | C29: NW24091911HL | D29: Dương Thị Dung | E29: PW | F29: 06.09.2024 | G29: 18.09.2024 | H29: 13 | I29: Công nhân xin nghỉ việc
B30: 28 | C30: NW24090284MD | D30: Ma Văn Thành Thông | E30: PW | F30: 16.09.2024 | G30: 17.09.2024 | H30: 2 | I30: Nghỉ quá 2 ngày không lý do
B31: 29 | C31: NW24090129HU | D31: La Thị Bình Yên | E31: PW | F31: 17.09.2024 | G31: 18.09.2024 | H31: 2 | I31: Nghỉ quá 2 ngày không lý do
B32: 30 | C32: NW24090056LV | D32: Nguyễn Duy Khánh | E32: P | F32: 05.09.2024 | G32: 18.09.2024 | H32: 13 | I32: Nghỉ không lý do 2 ngày | J32: 878872133
B33: 31 | C33: NW24090282MD | D33: Hoàng Phúc Tài | E33: P | F33: 16.09.2024 | G33: 18.09.2024 | H33: 2 | I33: Nghỉ không lý do 2 ngày | J33: 369734249
B34: 32 | C34: NW24091935HL | D34: Phùng Quang Huy | E34: P | F34: 16.09.2024 | G34: 18.09.2024 | H34: 2 | I34: Nghỉ không lý do 2 ngày | J34: 876773458
B35: 33 | C35: NW24090112HU | D35: Nguyễn Thị Bích Ngọc | E35: P | F35: 16.09.2024 | G35: 18.09.2024 | H35: 2 | I35: Nghỉ không lý do 2 ngày | J35: 921729422
B36: 34 | C36: NW24090110HU | D36: Vi Văn Chuyền | E36: P | F36: 13.09.2024 | G36: 18.09.2024 | H36: 5 | I36: Bỏ việc | J36: 973598209
B37: 35 | C37: NW24090096HU | D37: Dương Quốc Khánh | E37: P | F37: 12.09.2024 | G37: 18.09.2024 | H37: 6 | I37: Bỏ việc | J37: 968635372
B38: 36 | C38: NW24090097HU | D38: Vũ Đức Hoàng | E38: P | F38: 12.09.2024 | G38: 18.09.2024 | H38: 6 | I38: Bỏ việc | J38: 386630903
B39: 37 | C39: NW24092113HM | D39: Vũ Ngọc Linh | E39: PW | F39: 12.09.2024 | G39: 16.09.2024 | H39: 5 | I39: Nghỉ quá 2 ngày không lý do
B40: 38 | C40: NW24092112HM | D40: Nguyễn Minh Tâm | E40: PW | F40: 12.09.2024 | G40: 16.09.2024 | H40: 5 | I40: Nghỉ quá 2 ngày không lý do
B41: 39 | C41: NW24092111HM | D41: Phạm Khánh Ly | E41: PW | F41: 12.09.2024 | G41: 16.09.2024 | H41: 5 | I41: Nghỉ quá 2 ngày không lý do
B42: 40 | C42: NW24090278MD | D42: Hoàng Thị Hải Yến | E42: PW | F42: 12.09.2024 | G42: 16.09.2024 | H42: 5 | I42: Nghỉ quá 2 ngày không lý do
...

Sheet chuyên ca
A1: DS CHUYÊN CA ĐÊM
A2: STT | B2: Mã nhân viên | C2: Họ tên | D2: Ngày vào | E2: Vendor
A3: 1 | B3: NW24090414MA | C3: Nguyễn Tiến Thế | D3: =VLOOKUP(B3,TT!$B:$O,11,0) -> 45553 | E3: MA
A4: 2 | B4: NW24090413MA | C4: Nguyễn Thành Nam | D4: =VLOOKUP(B4,TT!$B:$O,11,0) -> 45553 | E4: MA
A5: 3 | B5: NW24090407MA | C5: Diệp Văn Mạnh | D5: =VLOOKUP(B5,TT!$B:$O,11,0) -> 45552 | E5: MA
A6: 4 | B6: NW24090417MA | C6: Đỗ Mạnh Thiệp | D6: =VLOOKUP(B6,TT!$B:$O,11,0) -> 45556 | E6: MA | F6: nghỉ việc
A7: 5 | B7: NW24090349CE | C7: Trần Thị Cẩm Tú | D7: =VLOOKUP(B7,TT!$B:$O,11,0) -> 45558 | E7: HN
A8: 6 | B8: NW24090350CE | C8: Dương Thị Đào | D8: =VLOOKUP(B8,TT!$B:$O,11,0) -> 45558 | E8: HN
A9: 7 | B9: NW24090351CE | C9: Nguyễn Thị Thu Hương | D9: =VLOOKUP(B9,TT!$B:$O,11,0) -> 45558 | E9: HN
A10: 8 | B10: NW24090296MD | C10: Thào Mí Sò | D10: =VLOOKUP(B10,TT!$B:$O,11,0) -> 45556 | E10: MD
A11: 9 | B11: NW24090297MD | C11: Sùng Đại Hùng | D11: =VLOOKUP(B11,TT!$B:$O,11,0) -> 45556 | E11: MD
A12: 10 | B12: NW24090298MD | C12: Sùng Mí Tiến | D12: =VLOOKUP(B12,TT!$B:$O,11,0) -> 45556 | E12: MD
A13: 11 | B13: NW24090299MD | C13: Thào Mí Nô | D13: =VLOOKUP(B13,TT!$B:$O,11,0) -> 45556 | E13: MD
A14: 12 | B14: NW24090300MD | C14: Ly Mí Vàng | D14: =VLOOKUP(B14,TT!$B:$O,11,0) -> 45556 | E14: MD
