Workbook

Sheet 10.08
C2: 근태 상황 보고서 | Q2: 보고 부서 | T2: 인사팀
Q3: 작성자 | T3: Pham Thi Nhung
Q4: 페이지 번호 | T4: 45514
Q5: 작성일자 | T5: 45514
C7: 근태 일자 : 2024 년 08월 10 | X7: (단위 : 명)
C9: 구분 | E9: 관리(QL) | G9: 제조 기술 (EQM) | I9: 관리(HQ) | J9: 생산(SX) | N9: 품질(QC) | Q9: 자재(MM) | T9: 영업(SM) | W9: 합계 | AA9: Total
E10: 간접 1 (G.T) | F10: 직접 1 (T.T) | G10: 간접 1 (G.T) | H10: 직접 1 (T.T) | J10: 간접 1 (G.T) | K10: 직접 1 (T.T) | L10: 간접 2 (G.T) | M10: 직접 2 (T.T) | N10: 간접 1 (G.T) | O10: 직접 1 (T.T) | P10: 직접 2 (T.T) | Q10: 간접 1 (G.T) | R10: 직접 1 (T.T) | S10: 직접 2 (T.T) | T10: 간접 1 (G.T) | U10: 직접 1 (T.T) | V10: 직접 2 (T.T) | W10: 간접 1 (G.T) | X10: 직접 1 (T.T) | Y10: 간접 2 (G.T) | Z10: 직접 2 (T.T)
C11: 전체 (Tong) | D11: 총 인원수(TOTAL) | E11: =E17+E24 -> 22 | F11: =F17+F24 -> 15 | G11: =G17+G24 -> 58 | H11: =H17+H24 -> 21 | I11: =I17+I24 -> 5 | J11: =J17+J24 -> 106 | K11: =K17+K24 -> 374 | L11: =L17+L24 -> 3 | ... V11: =V17+V24 -> 0 | W11: =E11+G11+J11+N11+Q11+I11+T11 -> 269 | X11: =+F11+H11+K11+O11+R11+U11 -> 622 | Y11: =+L11 -> 3 | Z11: =+M11+P11+S11+V11 -> 59 | AA11: =SUM(W11:Z11) -> 953 | AD11: =+W11+X11-I11 -> 886
D12: 출근 인원수(DL) | E12: =E18+E25 -> 7 | F12: =F18+F25 -> 0 | G12: =G18+G25 -> 0 | H12: =H18+H25 -> 0 | I12: =I18+I25 -> 0 | J12: =J18+J25 -> 0 | K12: =K18+K25 -> 0 | L12: =L18+L25 -> 0 | ... V12: =V18+V25 -> 0 | W12: =E12+G12+J12+N12+Q12+I12+T12 -> 7 | X12: =+F12+H12+K12+O12+R12+U12 -> 0 | Y12: =+L12 -> 0 | Z12: =+M12+P12+S12+V12 -> 0 | AA12: =SUM(W12:Z12) -> 7 | AD12: =+W12+X12-I12 -> 7
D13: 결근인원수(V) | E13: =E11-E12 -> 15 | F13: =F11-F12 -> 15 | G13: =G11-G12 -> 58 | H13: =H11-H12 -> 21 | I13: =I11-I12 -> 5 | J13: =J11-J12 -> 106 | K13: =K11-K12 -> 374 | L13: =L11-L12 -> 3 | ... V13: =V11-V12 -> 0 | W13: =E13+G13+J13+N13+Q13+I13+T13 -> 262 | X13: =+F13+H13+K13+O13+R13+U13 -> 622 | Y13: =+L13 -> 3 | Z13: =+M13+P13+S13+V13 -> 59 | AA13: =SUM(W13:Z13) -> 946 | AD13: =+W11+X11 -> 891
D14: 출근율(%) | E14: =IFERROR(E12/E11,0) -> 0.31818182 | F14: =IFERROR(F12/F11,0) -> 0 | G14: =IFERROR(G12/G11,0) -> 0 | H14: =IFERROR(H12/H11,0) -> 0 | I14: =IFERROR(I12/I11,0) -> 0 | J14: =IFERROR(J12/J11,0) -> 0 | K14: =IFERROR(K12/K11,0) -> 0 | L14: =IFERROR(L12/L11,0) -> 0 | ... Z14: =IFERROR(Z12/Z11,0) -> 0 | AA14: =+AA12/AA11 -> 0.0073452256
D15: 부서별 출근 인원수 | E15: =+E12+F12 -> 7 | G15: =+G12+H12 -> 0 | I15: =+I12 -> 0 | J15: =SUM(J12:M12) -> 0 | N15: =SUM(N12:P12) -> 0 | Q15: =SUM(Q12:S12) -> 0 | T15: =SUM(T12:V12) -> 0 | W15: =SUM(W12:Z12) -> 7
D16: 점유율(%) | E16: =E15/AA12 -> 1 | G16: =G15/AA12 -> 0 | I16: =I15/AA12 -> 0 | J16: =J15/$AA$12 -> 0 | N16: =N15/$AA$12 -> 0 | Q16: =Q15/$AA$12 -> 0 | T16: =T15/$AA$12 -> 0 | W16: =W15/$AA$12 -> 1
C17: 주간 (Ca Ngay) | D17: 총 인원수(TOTAL) | E17: 18 | F17: 7 | G17: 38 | H17: 13 | I17: 5 | J17: 56 | K17: 195 | L17: 2 | M17: 9 | N17: 24 | O17: 59 | P17: 12 | Q17: 15 | R17: 29 | S17: 0 | T17: 9 | U17: 19 | V17: 0 | W17: =E17+G17+J17+N17+Q17+I17+T17 -> 165 | X17: =+F17+H17+K17+O17+R17+U17 -> 322 | Y17: =+L17 -> 2 | Z17: =+M17+P17+S17+V17 -> 21 | AA17: =SUM(W17:Z17) -> 510
D18: 출근 인원수(DL) | E18: =+E17-SUM(E19:E22) -> 7 | F18: =+F17-SUM(F19:F22) -> 0 | G18: =+G17-SUM(G19:G22) -> 0 | H18: =+H17-SUM(H19:H22) -> 0 | I18: =+I17-SUM(I19:I22) -> 0 | J18: =+J17-SUM(J19:J22) -> 0 | K18: =+K17-SUM(K19:K22) -> 0 | L18: =+L17-SUM(L19:L22) -> 0 | ... V18: =+V17-SUM(V19:V22) -> 0 | W18: =E18+G18+J18+N18+Q18+I18+T18 -> 7 | X18: =+F18+H18+K18+O18+R18+U18 -> 0 | Y18: =+L18 -> 0 | Z18: =+M18+P18+S18+V18 -> 0 | AA18: =SUM(W18:Z18) -> 7
D19: 무단결근(Ko.Ly Do) | W19: =E19+G19+J19+N19+Q19+I19+T19 -> 0 | X19: =+F19+H19+K19+O19+R19+U19 -> 0 | Y19: =+L19 -> 0 | Z19: =+M19+P19+S19+V19 -> 0 | AA19: =SUM(W19:Z19) -> 0
D20: 휴가(Co Ly Do) | W20: =E20+G20+J20+N20+Q20+I20+T20 -> 0 | X20: =+F20+H20+K20+O20+R20+U20 -> 0 | Y20: =+L20 -> 0 | Z20: =+M20+P20+S20+V20 -> 0 | AA20: =SUM(W20:Z20) -> 0
D21: 기타(Khac) | E21: 11 | F21: 7 | G21: 38 | H21: 13 | I21: 5 | J21: 56 | K21: 195 | L21: 2 | M21: 9 | N21: 24 | O21: 59 | P21: 12 | Q21: 15 | R21: 29 | S21: 0 | T21: 9 | U21: 19 | V21: 0 | W21: =E21+G21+J21+N21+Q21+I21+T21 -> 158 | X21: =+F21+H21+K21+O21+R21+U21 -> 322 | Y21: =+L21 -> 2 | Z21: =+M21+P21+S21+V21 -> 21 | AA21: =SUM(W21:Z21) -> 503
D22: 퇴사 (Nghi viec) | W22: =E22+G22+J22+N22+Q22+I22+T22 -> 0 | X22: =+F22+H22+K22+O22+R22+U22 -> 0 | Y22: =+L22 -> 0 | Z22: =+M22+P22+S22+V22 -> 0 | AA22: =SUM(W22:Z22) -> 0
D23: 출근율(%) | E23: =IFERROR(E18/E17,0) -> 0.38888889 | F23: =IFERROR(F18/F17,0) -> 0 | G23: =IFERROR(G18/G17,0) -> 0 | H23: =IFERROR(H18/H17,0) -> 0 | I23: =IFERROR(I18/I17,0) -> 0 | J23: =IFERROR(J18/J17,0) -> 0 | K23: =IFERROR(K18/K17,0) -> 0 | L23: =IFERROR(L18/L17,0) -> 0 | ... Z23: =IFERROR(Z18/Z17,0) -> 0 | AA23: =+AA18/AA17 -> 0.01372549
C24: 야간 (Ca Dem) | D24: 총 인원수(TOTAL) | E24: 4 | F24: 8 | G24: 20 | H24: 8 | I24: 0 | J24: 50 | K24: 179 | L24: 1 | M24: 19 | N24: 16 | O24: 61 | P24: 16 | Q24: 7 | R24: 25 | S24: 3 | T24: 7 | U24: 19 | V24: 0 | W24: =E24+G24+J24+N24+Q24+I24+T24 -> 104 | X24: =+F24+H24+K24+O24+R24+U24 -> 300 | Y24: =+L24 -> 1 | Z24: =+M24+P24+S24+V24 -> 38 | AA24: =SUM(W24:Z24) -> 443
D25: 출근 인원수(DL) | E25: =+E24-SUM(E26:E29) -> 0 | F25: =+F24-SUM(F26:F29) -> 0 | G25: =+G24-SUM(G26:G29) -> 0 | H25: =+H24-SUM(H26:H29) -> 0 | I25: =+I24-SUM(I26:I29) -> 0 | J25: =+J24-SUM(J26:J29) -> 0 | K25: =+K24-SUM(K26:K29) -> 0 | L25: =+L24-SUM(L26:L29) -> 0 | ... V25: =+V24-SUM(V26:V29) -> 0 | W25: =E25+G25+J25+N25+Q25+I25+T25 -> 0 | X25: =+F25+H25+K25+O25+R25+U25 -> 0 | Y25: =+L25 -> 0 | Z25: =+M25+P25+S25+V25 -> 0 | AA25: =SUM(W25:Z25) -> 0
D26: 무단결근(Ko.Ly Do) | W26: =E26+G26+J26+N26+Q26+I26+T26 -> 0 | X26: =+F26+H26+K26+O26+R26+U26 -> 0 | Y26: =+L26 -> 0 | Z26: =+M26+P26+S26+V26 -> 0 | AA26: =SUM(W26:Z26) -> 0
D27: 휴가(Co Ly Do) | W27: =E27+G27+J27+N27+Q27+I27+T27 -> 0 | X27: =+F27+H27+K27+O27+R27+U27 -> 0 | Y27: =+L27 -> 0 | Z27: =+M27+P27+S27+V27 -> 0 | AA27: =SUM(W27:Z27) -> 0
D28: 기타(Khac) | E28: 4 | F28: 8 | G28: 20 | H28: 8 | I28: 0 | J28: 50 | K28: 179 | L28: 1 | M28: 19 | N28: 16 | O28: 61 | P28: 16 | Q28: 7 | R28: 25 | S28: 3 | T28: 7 | U28: 19 | V28: 0 | W28: =E28+G28+J28+N28+Q28+I28+T28 -> 104 | X28: =+F28+H28+K28+O28+R28+U28 -> 300 | Y28: =+L28 -> 1 | Z28: =+M28+P28+S28+V28 -> 38 | AA28: =SUM(W28:Z28) -> 443
D29: 퇴사 (Nghi viec) | W29: =E29+G29+J29+N29+Q29+I29+T29 -> 0 | X29: =+F29+H29+K29+O29+R29+U29 -> 0 | Y29: =+L29 -> 0 | Z29: =+M29+P29+S29+V29 -> 0 | AA29: =SUM(W29:Z29) -> 0
D30: 출근율(%) | E30: =IFERROR(E25/E24,0) -> 0 | F30: =IFERROR(F25/F24,0) -> 0 | G30: =IFERROR(G25/G24,0) -> 0 | H30: =IFERROR(H25/H24,0) -> 0 | I30: =IFERROR(I25/I24,0) -> 0 | J30: =IFERROR(J25/J24,0) -> 0 | K30: =IFERROR(K25/K24,0) -> 0 | L30: =IFERROR(L25/L24,0) -> 0 | ... Z30: =IFERROR(Z25/Z24,0) -> 0 | AA30: =+AA25/AA24 -> 0

Sheet Kangatang

Sheet Kangatang_2

Sheet Kangatang_3

Sheet Kangatang_4

Sheet Kangatang_5

Sheet Kangatang_6

Sheet Kangatang_7

Sheet Kangatang_8

Sheet Kangatang_9

Sheet Kangatang_10

Sheet Kangatang_11

Sheet Kangatang_12

Sheet Kangatang_13

Sheet Kangatang_14

Sheet Kangatang_15

Sheet Kangatang_16

Sheet Kangatang_17

Sheet Kangatang_18

Sheet Kangatang_19

Sheet Kangatang_20

Sheet Kangatang_21

Sheet Kangatang_22

Sheet Kangatang_23

Sheet Kangatang_24

Sheet Kangatang_25

Sheet Kangatang_26

Sheet Kangatang_27

Sheet Kangatang_28

Sheet Kangatang_29

Sheet Kangatang_30

Sheet Kangatang_31

Sheet Kangatang_32

Sheet Kangatang_33

Sheet Kangatang_34

Sheet Kangatang_35

Sheet Kangatang_36

Sheet Kangatang_37

Sheet Kangatang_38

Sheet Kangatang_39

Sheet Kangatang_40

Sheet Kangatang_41

Sheet Kangatang_42

Sheet Kangatang_43

Sheet Kangatang_44

Sheet Kangatang_45

Sheet Kangatang_46

Sheet Kangatang_47

Sheet Kangatang_48

Sheet Kangatang_49

Sheet Kangatang_50

Sheet Kangatang_51

Sheet Kangatang_52

Sheet Kangatang_53

Sheet Kangatang_54

Sheet Kangatang_55

Sheet Kangatang_56

Sheet Kangatang_57

Sheet Kangatang_58

Sheet Kangatang_59

Sheet Kangatang_60

Sheet Kangatang_61

Sheet Kangatang_62

Sheet Kangatang_63

Sheet Kangatang_64

Sheet Kangatang_65

Sheet Kangatang_66

Sheet Kangatang_67

Sheet Kangatang_68

Sheet Kangatang_69

Sheet Kangatang_70

Sheet Kangatang_71

Sheet Kangatang_72

Sheet Kangatang_73

Sheet Kangatang_74

Sheet Kangatang_75

Sheet Kangatang_76

Sheet Kangatang_77

Sheet Kangatang_78

Sheet Kangatang_79

Sheet Kangatang_80

Sheet Kangatang_81

Sheet Kangatang_82

Sheet Kangatang_83

Sheet Kangatang_84

Sheet Kangatang_85

Sheet Kangatang_86

Sheet Kangatang_87

Sheet Kangatang_88

Sheet Kangatang_89

Sheet Kangatang_90

Sheet Kangatang_91

Sheet Kangatang_92

Sheet Kangatang_93

Sheet Kangatang_94

Sheet Kangatang_95

Sheet Kangatang_96

Sheet Kangatang_97

Sheet Kangatang_98

Sheet Kangatang_99

Sheet Kangatang_100

Sheet Kangatang_101

Sheet Kangatang_102

Sheet Kangatang_103

Sheet Kangatang_104

Sheet Kangatang_105

Sheet Kangatang_106

Sheet Kangatang_107

Sheet Kangatang_108

Sheet Kangatang_109

Sheet Kangatang_110

Sheet Kangatang_111

Sheet Kangatang_112

Sheet Kangatang_113

Sheet Kangatang_114

Sheet Kangatang_115

Sheet Kangatang_116

Sheet Kangatang_117

Sheet Kangatang_118

Sheet Kangatang_119

Sheet Kangatang_120

Sheet Kangatang_121

Sheet Kangatang_122

Sheet Kangatang_123

Sheet Kangatang_124

Sheet Kangatang_125

Sheet Kangatang_126

Sheet Kangatang_127

Sheet Kangatang_128

Sheet Kangatang_129

Sheet Kangatang_130

Sheet Kangatang_131

Sheet Kangatang_132

Sheet Kangatang_133

Sheet Kangatang_134

Sheet Kangatang_135

Sheet Kangatang_136

Sheet Kangatang_137

Sheet Kangatang_138

Sheet Kangatang_139

Sheet Kangatang_140

Sheet Kangatang_141

Sheet Kangatang_142

Sheet Kangatang_143

Sheet Kangatang_144

Sheet Kangatang_145

Sheet Kangatang_146

Sheet Kangatang_147

Sheet Kangatang_148

Sheet Kangatang_149

Sheet Kangatang_150

Sheet Kangatang_151

Sheet Kangatang_152

Sheet Kangatang_153

Sheet Kangatang_154

Sheet Kangatang_155

Sheet Kangatang_156

Sheet Kangatang_157

Sheet Kangatang_158

Sheet Kangatang_159

Sheet Kangatang_160

Sheet Kangatang_161

Sheet Kangatang_162

Sheet Kangatang_163

Sheet Kangatang_164

Sheet Kangatang_165

Sheet Kangatang_166

Sheet Kangatang_167

Sheet Kangatang_168

Sheet Kangatang_169

Sheet Kangatang_170

Sheet 근태종합(02월)
C3: 근태 종합 보고(02월) | K3: 보고 부서 | M3: 인사팀 | P3: 비고 | Q3: 간접1 (G.T) | S3: Người HQ, TT, ĐT, CN,DERI,TP,Nhân viên, TF, Kiting, Vệ sinh sx, Tray, Lxe
K4: 작성자 | M4: Pham Thi Nhung | Q4: 직접 1 (T.T) | S4: Công nhân bộ phận P, E,Q,M,S,VPQL
K5: 페이지 번호 | M5: 46062 | Q5: 간접 2 (G.T) | S5: Công nhân thời vụ là Transfer , vệ sinh sản xuất, kitting
K6: 작성일자 | M6: 46062 | Q6: 직접 2 (T.T) | S6: Công nhân thời vụ bp P, Q,S,M
AO7: =+AO8-AO23 -> 0
C10: 근태 일자 : 2026 년 02 월 09
C11: 구 분 | F11: 2026 | G11: 1 계 | H11: 2계 | I11: 1 | J11: 2 | K11: 3 | L11: 4 | M11: 5 | N11: 6 | O11: 7 | P11: 8 | Q11: 9 | R11: 10 | S11: 11 | T11: 12 | U11: 13 | V11: 14 | W11: 15 | X11: 16 | Y11: 17 | Z11: 18 | AA11: 19 | AB11: 20 | AC11: 21 | AD11: 22 | AE11: 23 | AF11: 24 | AG11: 25 | AH11: 26 | AI11: 27 | AJ11: 28 | AK11: 29 | AL11: 30 | AM11: 31
I12: Sun | J12: No Sunday | K12: No Sunday | L12: No Sunday | M12: No Sunday | N12: No Sunday | O12: No Sunday | P12: Sun | Q12: No Sunday | R12: No Sunday | S12: No Sunday | T12: No Sunday | U12: No Sunday | V12: No Sunday | W12: Sun | X12: No Sunday | Y12: No Sunday | Z12: No Sunday | AA12: No Sunday | AB12: No Sunday | AC12: No Sunday | AD12: Sun | AE12: No Sunday | AF12: No Sunday | AG12: No Sunday | AH12: No Sunday | AI12: No Sunday | AJ12: No Sunday
C13: 전체 (Tong) | E13: Total | F13: =AVERAGE(G13:H13) -> 592.19231 | G13: 1184.3846 | H13: =IFERROR(AVERAGEIFS(I13:AM13,I13:AM13,">0.01",$I$12:$AM$12,"No Sunday"),0) -> 0 | I13: =SUM(I14:I17) -> 1323
D14: 정규 (CT) | E14: 간접 1 (G.T) | F14: =AVERAGE(G14:H14) -> 144.51923 | G14: 289.03846 | H14: =IFERROR(AVERAGEIFS(I14:AM14,I14:AM14,">100",$I$12:$AM$12,"No Sunday"),0) -> 0 | I14: =+'01.02'!$Y$11 -> 289
E15: 직접 1 (T.T) | F15: =AVERAGE(G15:H15) -> 217.78846 | G15: 435.57692 | H15: =IFERROR(AVERAGEIFS(I15:AM15,I15:AM15,">200",$I$12:$AM$12,"No Sunday"),0) -> 0 | I15: =+'01.02'!$Z$11 -> 435
D16: 용역 (TV) | E16: 간접 2 (G.T) | F16: =AVERAGE(G16:H16) -> 2.8076923 | G16: 5.6153846 | H16: =IFERROR(AVERAGEIFS(I16:AM16,I16:AM16,">0.01",$I$12:$AM$12,"No Sunday"),0) -> 0 | I16: =+'01.02'!$AA$11 -> 5
E17: 직접 2 (T.T) | F17: =AVERAGE(G17:H17) -> 227.07692 | G17: 454.15385 | H17: =IFERROR(AVERAGEIFS(I17:AM17,I17:AM17,">20",$I$12:$AM$12,"No Sunday"),0) -> 0 | I17: =+'01.02'!$AB$11 -> 594
C18: Ty le tong | E18: Total | F18: =AVERAGE(I18:I18) -> 1 | G18: 1 | H18: =AVERAGE(I18:M18,O18:T18,V18:AA18,AC18:AH18,AJ18:AM18) -> 1 | I18: =SUM(I19:I22) -> 1
D19: 정규 (CT) | E19: 간접 1 (G.T) | F19: =AVERAGE(G19:H19) -> 0.23125376 | G19: 0.24406458 | H19: =AVERAGE(I19:M19,O19:T19,V19:AA19,AC19:AH19,AJ19:AM19) -> 0.21844293 | I19: =+I14/$I$13 -> 0.21844293
E20: 직접 1 (T.T) | F20: =AVERAGE(G20:H20) -> 0.34844808 | G20: 0.36809798 | H20: =AVERAGE(I20:M20,O20:T20,V20:AA20,AC20:AH20,AJ20:AM20) -> 0.32879819 | I20: =+I15/$I$13 -> 0.32879819
D21: 용역 (TV) | E21: 간접 2 (G.T) | F21: =AVERAGE(G21:H21) -> 0.004276934 | G21: 0.0047745785 | H21: =AVERAGE(I21:M21,O21:T21,V21:AA21,AC21:AH21,AJ21:AM21) -> 0.0037792895 | I21: =+I16/$I$13 -> 0.0037792895
E22: 직접 2 (T.T) | F22: =AVERAGE(G22:H22) -> 0.41602123 | G22: 0.38306286 | H22: =AVERAGE(I22:M22,O22:T22,V22:AA22,AC22:AH22,AJ22:AM22) -> 0.44897959 | I22: =+I17/$I$13 -> 0.44897959
C23: 출근인원 (Di lam) | E23: Total | F23: =SUM(F25:F28) -> 521.40385 | G23: 1043.4615 | H23: =SUM(H25:H28) -> 0 | I23: =SUM(I25:I28) -> 1323
D24: +/- | F24: =AVERAGE(G24:J24) -> -46.974359 | G24: -140.92308 | H24: =H23-H13 -> 0 | I24: =I23-I13 -> 0
D25: 정규 (CT) | E25: 간접1(G.T) | F25: =AVERAGE(G25:H25) -> 137.63462 | G25: 275.26923 | H25: =IFERROR(AVERAGEIFS(I25:AM25,I25:AM25,">60",$I$12:$AM$12,"No Sunday"),0) -> 0 | I25: =+'01.02'!$Y$12 -> 289
E26: 직접 1 (T.T) | F26: =AVERAGE(G26:H26) -> 208.88462 | G26: 417.76923 | H26: =IFERROR(AVERAGEIFS(I26:AM26,I26:AM26,">200",$I$12:$AM$12,"No Sunday"),0) -> 0 | I26: =+'01.02'!$Z$12 -> 435
D27: 용역 (TV) | E27: 간접 2 (G.T) | F27: =AVERAGE(G27:H27) -> 2.3846154 | G27: 4.7692308 | H27: =IFERROR(AVERAGEIFS(I27:AM27,I27:AM27,">0.01",$I$12:$AM$12,"No Sunday"),0) -> 0 | I27: =+'01.02'!$AA$12 -> 5
E28: 직접 2 (T.T) | F28: =AVERAGE(G28:H28) -> 172.5 | G28: 345 | H28: =IFERROR(AVERAGEIFS(I28:AM28,I28:AM28,">30",$I$12:$AM$12,"No Sunday"),0) -> 0 | I28: =+'01.02'!$AB$12 -> 594
C29: 출근율 (Ty le di lam) | E29: Total | F29: =AVERAGE(G29:H29) -> 0.44050789 | G29: 0.88101578 | H29: =IFERROR((H23/H13),0) -> 0 | I29: =IFERROR(I23/I13,0) -> 1
D30: 정규 (CT) | E30: 간접1 (G.T) | F30: =AVERAGE(G30:H30) -> 0.47618097 | G30: 0.95236194 | H30: =IFERROR((H25/H14),0) -> 0 | I30: =IFERROR(I25/I14,0) -> 1
E31: 직접 1 (T.T) | F31: =AVERAGE(G31:H31) -> 0.4795585 | G31: 0.959117 | H31: =IFERROR((H26/H15),0) -> 0 | I31: =IFERROR(I26/I15,0) -> 1
D32: 용역 (TV) | E32: 간접 2 (G.T) | F32: =AVERAGE(G32:H32) -> 0.42465753 | G32: 0.84931507 | H32: =IFERROR((H27/H16),0) -> 0 | I32: =IFERROR(I27/I16,0) -> 1
E33: 직접 2 (T.T) | F33: =AVERAGE(G33:H33) -> 0.38054709 | G33: 0.76109417 | H33: =IFERROR((H28/H17),0) -> 0 | I33: =IFERROR(I28/I17,0) -> 1
C34: 퇴사인원 Nghi Viec | E34: Total | F34: =SUM(G34:H34) -> 1149 | G34: 1148 | H34: =SUM(H35:H38) -> 1 | I34: =SUM(I35:I38) -> 1
D35: 정규 (CT) | E35: 간접1 (G.T) | F35: =SUM(G35:H35) -> 7 | G35: 7 | H35: =SUM(I35:AM35) -> 0
E36: 직접 1 (T.T) | F36: =SUM(G36:H36) -> 5 | G36: 5 | H36: =SUM(I36:AM36) -> 0
D37: 용역 (TV) | E37: 간접 2 (G.T) | F37: =SUM(G37:H37) -> 0 | G37: 0 | H37: =SUM(I37:AM37) -> 0
E38: 직접 2 (T.T) | F38: =SUM(G38:H38) -> 1137 | G38: 1136 | H38: =SUM(I38:AM38) -> 1 | I38: 1
C39: 퇴사율 Ty Le Nghi Viec | E39: Total % | F39: =AVERAGE(G39:H39) -> 0.48463986 | G39: 0.96927973 | H39: =IFERROR((H34/H13),0) -> 0 | I39: =SUM(I40:I43) -> 0.0007558579
D40: 정규 (CT) | E40: 간접1 (G.T) | F40: =AVERAGE(G40:H40) -> 0.0017412944 | G40: 0.0034825887 | H40: =SUM(J40:AN40) -> 0 | I40: =IFERROR(I35/I13,0) -> 0
E41: 직접 1 (T.T) | F41: =AVERAGE(G41:H41) -> 0.00213348 | G41: 0.0042669599 | H41: =SUM(J41:AN41) -> 0 | I41: =IFERROR(I36/I13,0) -> 0
D42: 용역 (TV) | E42: 간접 2 (G.T) | F42: =AVERAGE(G42:H42) -> 0 | G42: 0 | H42: =SUM(J42:AN42) -> 0 | I42: =IFERROR(I37/I13,0) -> 0
E43: 직접 2 (T.T) | F43: =AVERAGE(G43:H43) -> 0.46570187 | G43: 0.93140373 | H43: =SUM(J43:AN43) -> 0 | I43: =IFERROR(I38/I13,0) -> 0.0007558579
C44: 퇴사인원 | E44: Total
...

Sheet 01.02
C2: 근태 상황 보고서 | S2: 보고 부서 | V2: 인사팀
S3: 작성자 | V3: Pham Thi Nhung
S4: 페이지 번호 | V4: 46054
S5: 작성일자 | V5: 46054
C7: 근태 일자 : 2026 년 02월 01 | Z7: (단위 : 명)
C9: 구분 | E9: 관리(QL) | H9: 제조 기술 (EQM) | K9: 관리(HQ) | L9: 생산(SX) | P9: 품질(QC) | S9: 자재(MM) | V9: 영업(SM) | Y9: 합계 | AC9: Total
E10: 간접 1 (G.T) | F10: 직접 1 (T.T) | G10: 직접 2 (T.T) | H10: 간접 1 (G.T) | I10: 직접 1 (T.T) | J10: 직접 2 (T.T) | L10: 간접 1 (G.T) | M10: 직접 1 (T.T) | N10: 간접 2 (G.T) | O10: 직접 2 (T.T) | P10: 간접 1 (G.T) | Q10: 직접 1 (T.T) | R10: 직접 2 (T.T) | S10: 간접 1 (G.T) | T10: 직접 1 (T.T) | U10: 직접 2 (T.T) | V10: 간접 1 (G.T) | W10: 직접 1 (T.T) | X10: 직접 2 (T.T) | Y10: 간접 1 (G.T) | Z10: 직접 1 (T.T) | AA10: 간접 2 (G.T) | AB10: 직접 2 (T.T)
C11: 전체 (Tong) | D11: 총 인원수(TOTAL) | E11: =E17+E24 -> 24 | F11: =F17+F24 -> 3 | G11: =G17+G24 -> 1 | H11: =H17+H24 -> 63 | I11: =I17+I24 -> 6 | J11: =J17+J24 -> 3 | K11: =K17+K24 -> 4 | L11: =L17+L24 -> 110 | ... X11: =X17+X24 -> 7 | Y11: =E11+H11+L11+P11+S11+K11+V11 -> 289 | Z11: =I11+M11+Q11+T11+W11+F11 -> 435 | AA11: =+N11 -> 5 | AB11: =+O11+R11+U11+X11+G11+J11 -> 594 | AC11: =SUM(Y11:AB11) -> 1323
D12: 출근 인원수(DL) | E12: =E18+E25 -> 24 | F12: =F18+F25 -> 3 | G12: =G18+G25 -> 1 | H12: =H18+H25 -> 63 | I12: =I18+I25 -> 6 | J12: =J18+J25 -> 3 | K12: =K18+K25 -> 4 | L12: =L18+L25 -> 110 | ... X12: =X18+X25 -> 7 | Y12: =E12+H12+L12+P12+S12+K12+V12 -> 289 | Z12: =I12+M12+Q12+T12+W12+F12 -> 435 | AA12: =+N12 -> 5 | AB12: =+O12+R12+U12+X12+G12+J12 -> 594 | AC12: =SUM(Y12:AB12) -> 1323
D13: 결근인원수(V) | E13: =E11-E12 -> 0 | F13: =F11-F12 -> 0 | G13: =G11-G12 -> 0 | H13: =H11-H12 -> 0 | I13: =I11-I12 -> 0 | J13: =J11-J12 -> 0 | K13: =K11-K12 -> 0 | L13: =L11-L12 -> 0 | ... X13: =X11-X12 -> 0 | Y13: =E13+H13+L13+P13+S13+K13+V13 -> 0 | Z13: =I13+M13+Q13+T13+W13+F13 -> 0 | AA13: =+N13 -> 0 | AB13: =+O13+R13+U13+X13+G13+J13 -> 0 | AC13: =SUM(Y13:AB13) -> 0
D14: 출근율(%) | E14: =IFERROR(E12/E11,0) -> 1 | F14: =IFERROR(F12/F11,0) -> 1 | G14: =IFERROR(G12/G11,0) -> 1 | H14: =IFERROR(H12/H11,0) -> 1 | I14: =IFERROR(I12/I11,0) -> 1 | J14: =IFERROR(J12/J11,0) -> 1 | K14: =IFERROR(K12/K11,0) -> 1 | L14: =IFERROR(L12/L11,0) -> 1 | ... AB14: =IFERROR(AB12/AB11,0) -> 1 | AC14: =+AC12/AC11 -> 1
D15: 부서별 출근 인원수 | E15: =+E12+G12+F12 -> 28 | H15: =SUM(H12:J12) -> 72 | K15: =+K12 -> 4 | L15: =SUM(L12:O12) -> 853 | P15: =SUM(P12:R12) -> 226 | S15: =SUM(S12:U12) -> 86 | V15: =SUM(V12:X12) -> 54 | Y15: =SUM(Y12:AB12) -> 1323
D16: 점유율(%) | E16: =E15/AC12 -> 0.021164021 | H16: =H15/AC12 -> 0.054421769 | K16: =K15/AC12 -> 0.0030234316 | L16: =L15/$AC$12 -> 0.64474679 | P16: =P15/$AC$12 -> 0.17082389 | S16: =S15/$AC$12 -> 0.065003779 | V16: =V15/$AC$12 -> 0.040816327 | Y16: =Y15/$AC$12 -> 1
C17: 주간 (Ca Ngay) | D17: 총 인원수(TOTAL) | E17: 21 | F17: 2 | G17: 1 | H17: 34 | I17: 5 | J17: 3 | K17: 4 | L17: 63 | M17: 124 | N17: 0 | O17: 243 | P17: 24 | Q17: 67 | R17: 24 | S17: 19 | T17: 16 | U17: 12 | V17: 9 | W17: 16 | X17: 3 | Y17: =E17+H17+L17+P17+S17+K17+V17 -> 174 | Z17: =I17+M17+Q17+T17+W17+F17 -> 230 | AA17: =+N17 -> 0 | AB17: =+O17+R17+U17+X17+G17+J17 -> 286 | AC17: =SUM(Y17:AB17) -> 690
D18: 출근 인원수(DL) | E18: =+E17-SUM(E19:E22) -> 21 | F18: =+F17-SUM(F19:F22) -> 2 | G18: =+G17-SUM(G19:G22) -> 1 | H18: =+H17-SUM(H19:H22) -> 34 | I18: =+I17-SUM(I19:I22) -> 5 | J18: =+J17-SUM(J19:J22) -> 3 | K18: =+K17-SUM(K19:K22) -> 4 | L18: =+L17-SUM(L19:L22) -> 63 | ... X18: =+X17-SUM(X19:X22) -> 3 | Y18: =E18+H18+L18+P18+S18+K18+V18 -> 174 | Z18: =I18+M18+Q18+T18+W18+F18 -> 230 | AA18: =+N18 -> 0 | AB18: =+O18+R18+U18+X18+G18+J18 -> 286 | AC18: =SUM(Y18:AB18) -> 690
D19: 무단결근(Ko.Ly Do) | Y19: =E19+H19+L19+P19+S19+K19+V19 -> 0 | Z19: =I19+M19+Q19+T19+W19+F19 -> 0 | AA19: =+N19 -> 0 | AB19: =+O19+R19+U19+X19+G19+J19 -> 0 | AC19: =SUM(Y19:AB19) -> 0
D20: 휴가(Co Ly Do) | Y20: =E20+H20+L20+P20+S20+K20+V20 -> 0 | Z20: =I20+M20+Q20+T20+W20+F20 -> 0 | AA20: =+N20 -> 0 | AB20: =+O20+R20+U20+X20+G20+J20 -> 0 | AC20: =SUM(Y20:AB20) -> 0
D21: 기타(Khac) | Y21: =E21+H21+L21+P21+S21+K21+V21 -> 0 | Z21: =I21+M21+Q21+T21+W21+F21 -> 0 | AA21: =+N21 -> 0 | AB21: =+O21+R21+U21+X21+G21+J21 -> 0 | AC21: =SUM(Y21:AB21) -> 0
D22: 퇴사 (Nghi viec) | Y22: =E22+H22+L22+P22+S22+K22+V22 -> 0 | Z22: =I22+M22+Q22+T22+W22+F22 -> 0 | AA22: =+N22 -> 0 | AB22: =+O22+R22+U22+X22+G22+J22 -> 0 | AC22: =SUM(Y22:AB22) -> 0
D23: 출근율(%) | E23: =IFERROR(E18/E17,0) -> 1 | F23: =IFERROR(F18/F17,0) -> 1 | G23: =IFERROR(G18/G17,0) -> 1 | H23: =IFERROR(H18/H17,0) -> 1 | I23: =IFERROR(I18/I17,0) -> 1 | J23: =IFERROR(J18/J17,0) -> 1 | K23: =IFERROR(K18/K17,0) -> 1 | L23: =IFERROR(L18/L17,0) -> 1 | ... AB23: =IFERROR(AB18/AB17,0) -> 1 | AC23: =+AC18/AC17 -> 1
C24: 야간 (Ca Dem) | D24: 총 인원수(TOTAL) | E24: 3 | F24: 1 | G24: 0 | H24: 29 | I24: 1 | J24: 0 | L24: 47 | M24: 118 | N24: 5 | O24: 253 | P24: 16 | Q24: 51 | R24: 44 | S24: 13 | T24: 19 | U24: 7 | V24: 7 | W24: 15 | X24: 4 | Y24: =E24+H24+L24+P24+S24+K24+V24 -> 115 | Z24: =I24+M24+Q24+T24+W24+F24 -> 205 | AA24: =+N24 -> 5 | AB24: =+O24+R24+U24+X24+G24+J24 -> 308 | AC24: =SUM(Y24:AB24) -> 633
D25: 출근 인원수(DL) | E25: =+E24-SUM(E26:E29) -> 3 | F25: =+F24-SUM(F26:F29) -> 1 | G25: =+G24-SUM(G26:G29) -> 0 | H25: =+H24-SUM(H26:H29) -> 29 | I25: =+I24-SUM(I26:I29) -> 1 | J25: =+J24-SUM(J26:J29) -> 0 | K25: =+K24-SUM(K26:K29) -> 0 | L25: =+L24-SUM(L26:L29) -> 47 | ... X25: =+X24-SUM(X26:X29) -> 4 | Y25: =E25+H25+L25+P25+S25+K25+V25 -> 115 | Z25: =I25+M25+Q25+T25+W25+F25 -> 205 | AA25: =+N25 -> 5 | AB25: =+O25+R25+U25+X25+G25+J25 -> 308 | AC25: =SUM(Y25:AB25) -> 633
D26: 무단결근(Ko.Ly Do) | Y26: =E26+H26+L26+P26+S26+K26+V26 -> 0 | Z26: =I26+M26+Q26+T26+W26+F26 -> 0 | AA26: =+N26 -> 0 | AB26: =+O26+R26+U26+X26+G26+J26 -> 0 | AC26: =SUM(Y26:AB26) -> 0
D27: 휴가(Co Ly Do) | Y27: =E27+H27+L27+P27+S27+K27+V27 -> 0 | Z27: =I27+M27+Q27+T27+W27+F27 -> 0 | AA27: =+N27 -> 0 | AB27: =+O27+R27+U27+X27+G27+J27 -> 0 | AC27: =SUM(Y27:AB27) -> 0
D28: 기타(Khac) | Y28: =E28+H28+L28+P28+S28+K28+V28 -> 0 | Z28: =I28+M28+Q28+T28+W28+F28 -> 0 | AA28: =+N28 -> 0 | AB28: =+O28+R28+U28+X28+G28+J28 -> 0 | AC28: =SUM(Y28:AB28) -> 0
D29: 퇴사 (Nghi viec) | Y29: =E29+H29+L29+P29+S29+K29+V29 -> 0 | Z29: =I29+M29+Q29+T29+W29+F29 -> 0 | AA29: =+N29 -> 0 | AB29: =+O29+R29+U29+X29+G29+J29 -> 0 | AC29: =SUM(Y29:AB29) -> 0
D30: 출근율(%) | E30: =IFERROR(E25/E24,0) -> 1 | F30: =IFERROR(F25/F24,0) -> 1 | G30: =IFERROR(G25/G24,0) -> 0 | H30: =IFERROR(H25/H24,0) -> 1 | I30: =IFERROR(I25/I24,0) -> 1 | J30: =IFERROR(J25/J24,0) -> 0 | K30: =IFERROR(K25/K24,0) -> 0 | L30: =IFERROR(L25/L24,0) -> 1 | ... AB30: =IFERROR(AB25/AB24,0) -> 1 | AC30: =+AC25/AC24 -> 1
